Workbook

Sheet Parametry
A1: Prdel světa — balancovací sešit
A2: Legenda: modré číslo = vstup, který upravuješ. Černé = vzorec, nesahat. Žlutá = klíčové páky balancu.
A3: Zdroj všech čísel: design dokument v0.7 (kapitoly 3–7, 20). Kde je číslo odhad, je to řečeno v komentáři.
A5: Parametr | B5: Hodnota | C5: Klíč | D5: Zdroj / poznámka
A6: Škálování HP nepřátel za vlnu | B6: 1.15 | C6: hp_scale | D6: Dokument kap. 5: HP × 1,15^(vlna-1)
A7: Škálování počtu nepřátel za vlnu | B7: 1.08 | C7: count_scale | D7: Dokument kap. 5: počet × 1,08^(vlna-1)
A8: Cílová délka vlny (s) | B8: 45 | C8: wave_len | D8: Odhad: jak dlouho má trvat zabít celou vlnu, když je obrana OK
A9: Nádech mezi vlnami (s) | B9: 8 | C9: breath | D9: Dokument kap. 2
A10: Podíl potřebného DPS, který kryjí zbraně | B10: 0.7 | C10: dps_share | D10: Dokument kap. 6: 70 %, zbytek pasti a pláty
A11: Využití zbraní (uptime) | B11: 0.6 | C11: uptime | D11: Odhad: zbraně nestřílí pořád — mimo dostřel, přebíjení, roztáčení
A12: Exponent škálování odměn s HP | B12: 0.7 | C12: rew_k | D12: Odměna × (násobič HP)^exponent. 0 = odměny neškálují (model se rozpadne po vlně 12), 1 = škálují stejně jako HP (příliš lehké). 0,7 drží poměr 1,0–1,4 a ke konci mírně klesá.
A13: Startovní prachy | B13: 200 | C13: start_money | D13: Dokument kap. 7
A14: Bonus za vlnu (základ) | B14: 20 | C14: wave_bonus | D14: Dokument kap. 7: 20 + 5 × vlna
A15: Bonus za vlnu (na vlnu) | B15: 5 | C15: wave_bonus_per | D15: Dokument kap. 7
A16: Podíl prachů utracených za zbraně | B16: 0.6 | C16: money_to_weapons | D16: Odhad: zbytek jde na díly, opravy, pasti
A17: Násobič dmg L2 (+1 projektil) | B17: 2 | C17: l2_mult | D17: Dokument kap. 4.3: +1 projektil = 2× dmg u jednoprojektilových
... A22: HP jádra | B22: 1000 | C22: core_hp | D22: Dokument kap. 3.7

Sheet Díly
A1: Díl | B1: Typ | C1: HP | D1: Hmotnost (kg) | E1: Cena | F1: Síla prasknutí (N) | G1: HP na 1 prachy | H1: HP na 1 kg | I1: Poznámka
A2: Klacky | B2: konstrukce | C2: 40 | D2: 1 | E2: 5 | F2: 180 | G2: =IF(E2=0,0,C2/E2) -> 8 | H2: =IF(D2=0,0,C2/D2) -> 40 | I2: hoří
A3: Trámy | B3: konstrukce | C3: 120 | D3: 3 | E3: 20 | F3: 700 | G3: =IF(E3=0,0,C3/E3) -> 6 | H3: =IF(D3=0,0,C3/D3) -> 40 | I3: hoří pomalu
A4: Železo | B4: konstrukce | C4: 350 | D4: 8 | E4: 80 | F4: 2600 | G4: =IF(E4=0,0,C4/E4) -> 4.375 | H4: =IF(D4=0,0,C4/D4) -> 43.75 | I4: vodí elektřinu
A5: Grafit | B5: konstrukce | C5: 900 | D5: 4 | E5: 300 | F5: 6000 | G5: =IF(E5=0,0,C5/E5) -> 3 | H5: =IF(D5=0,0,C5/D5) -> 225 | I5: lehké, nehoří, vzácné
A6: Papír | B6: plát | C6: 30 | D6: 0.5 | E6: 3 | F6: 120 | G6: =IF(E6=0,0,C6/E6) -> 10 | H6: =IF(D6=0,0,C6/D6) -> 60
A7: Dřevo | B7: plát | C7: 100 | D7: 2 | E7: 15 | F7: 600 | G7: =IF(E7=0,0,C7/E7) -> 6.6666667 | H7: =IF(D7=0,0,C7/D7) -> 50
A8: Plech | B8: plát | C8: 250 | D8: 4 | E8: 50 | F8: 1800 | G8: =IF(E8=0,0,C8/E8) -> 5 | H8: =IF(D8=0,0,C8/D8) -> 62.5
A9: Ocel | B9: plát | C9: 600 | D9: 9 | E9: 180 | F9: 4000 | G9: =IF(E9=0,0,C9/E9) -> 3.3333333 | H9: =IF(D9=0,0,C9/D9) -> 66.666667
A10: Kolejnice | B10: plát | C10: 1400 | D10: 16 | E10: 500 | F10: 9000 | G10: =IF(E10=0,0,C10/E10) -> 2.8 | H10: =IF(D10=0,0,C10/D10) -> 87.5
A12: Síla prasknutí je odhad z prototypu (Part.swift, Tuning) — kalibrovat podle 'max síla ve spoji'.
A13: Cíl: HP na 1 prachy má klesat s vyšším stupněm (platíš za hustotu ochrany, ne za efektivitu), HP na 1 kg má růst (lepší materiál = lehčí ochrana).

Sheet Zbraně
A1: Zbraň | B1: Typ | C1: Dmg za výstřel | D1: Palba (za s) | E1: Projektilů | F1: Splash r (pt) | G1: Dostřel (pt) | H1: Cena | I1: Zpětný ráz | J1: DPS L1 (1 cíl) | K1: DPS na 1 prachy | L1: DPS L2 | M1: DPS L3 | N1: DPS L4 (dav) | O1: DPS L5 | P1: Cena L1–L5 celkem | Q1: Poznámka
A2: Kamenář | B2: P | C2: 8 | D2: 1.5 | E2: 1 | F2: 0 | G2: 250 | H2: 30 | I2: 0 | J2: =C2*D2*E2 -> 12 | K2: =IF(H2=0,0,J2/H2) -> 0.4 | L2: =J2*Parametry!$B$17 -> 24 | M2: =L2*Parametry!$B$18 -> 33.6 | N2: =M2*IF(F2>0,Parametry!$B$19,1) -> 33.6 | O2: =N2*Parametry!$B$20 -> 67.2 | P2: =H2*(1+0.8+1.2+1.8+2.5) -> 219
A3: Luk | B3: O | C3: 12 | D3: 1.2 | E3: 1 | F3: 0 | G3: 400 | H3: 50 | I3: 0 | J3: =C3*D3*E3 -> 14.4 | K3: =IF(H3=0,0,J3/H3) -> 0.288 | L3: =J3*Parametry!$B$17 -> 28.8 | M3: =L3*Parametry!$B$18 -> 40.32 | N3: =M3*IF(F3>0,Parametry!$B$19,1) -> 40.32 | O3: =N3*Parametry!$B$20 -> 80.64 | P3: =H3*(1+0.8+1.2+1.8+2.5) -> 365
A4: Kuš | B4: P | C4: 30 | D4: 0.5 | E4: 1 | F4: 0 | G4: 350 | H4: 90 | I4: 1 | J4: =C4*D4*E4 -> 15 | K4: =IF(H4=0,0,J4/H4) -> 0.16666667 | L4: =J4*Parametry!$B$17 -> 30 | M4: =L4*Parametry!$B$18 -> 42 | N4: =M4*IF(F4>0,Parametry!$B$19,1) -> 42 | O4: =N4*Parametry!$B$20 -> 84 | P4: =H4*(1+0.8+1.2+1.8+2.5) -> 657
A5: Dědova vzduchovka | B5: P | C5: 60 | D5: 0.3 | E5: 1 | F5: 0 | G5: 600 | H5: 150 | I5: 1 | J5: =C5*D5*E5 -> 18 | K5: =IF(H5=0,0,J5/H5) -> 0.12 | L5: =J5*Parametry!$B$17 -> 36 | M5: =L5*Parametry!$B$18 -> 50.4 | N5: =M5*IF(F5>0,Parametry!$B$19,1) -> 50.4 | O5: =N5*Parametry!$B$20 -> 100.8 | P5: =H5*(1+0.8+1.2+1.8+2.5) -> 1095 | Q5: průraz
A6: Kulomet z traktoru | B6: P | C6: 6 | D6: 8 | E6: 1 | F6: 0 | G6: 300 | H6: 250 | I6: 3 | J6: =C6*D6*E6 -> 48 | K6: =IF(H6=0,0,J6/H6) -> 0.192 | L6: =J6*Parametry!$B$17 -> 96 | M6: =L6*Parametry!$B$18 -> 134.4 | N6: =M6*IF(F6>0,Parametry!$B$19,1) -> 134.4 | O6: =N6*Parametry!$B$20 -> 268.8 | P6: =H6*(1+0.8+1.2+1.8+2.5) -> 1825
A7: Plamenomet | B7: P kužel | C7: 4 | D7: 1 | E7: 1 | F7: 40 | G7: 120 | H7: 200 | I7: 1 | J7: =C7*D7*E7 -> 4 | K7: =IF(H7=0,0,J7/H7) -> 0.02 | L7: =J7*Parametry!$B$17 -> 8 | M7: =L7*Parametry!$B$18 -> 11.2 | N7: =M7*IF(F7>0,Parametry!$B$19,1) -> 16.8 | O7: =N7*Parametry!$B$20 -> 33.6 | P7: =H7*(1+0.8+1.2+1.8+2.5) -> 1460 | Q7: dmg je DoT za s, palba = 1 = trvalý
A8: Harpuna | B8: P | C8: 20 | D8: 0.3 | E8: 1 | F8: 0 | G8: 300 | H8: 180 | I8: 4 | J8: =C8*D8*E8 -> 6 | K8: =IF(H8=0,0,J8/H8) -> 0.033333333 | L8: =J8*Parametry!$B$17 -> 12 | M8: =L8*Parametry!$B$18 -> 16.8 | N8: =M8*IF(F8>0,Parametry!$B$19,1) -> 16.8 | O8: =N8*Parametry!$B$20 -> 33.6 | P8: =H8*(1+0.8+1.2+1.8+2.5) -> 1314 | Q8: + přitažení, odhození
A9: Laser z DVD | B9: P průraz | C9: 90 | D9: 0.15 | E9: 1 | F9: 0 | G9: 500 | H9: 400 | I9: 0 | J9: =C9*D9*E9 -> 13.5 | K9: =IF(H9=0,0,J9/H9) -> 0.03375 | L9: =J9*Parametry!$B$17 -> 27 | M9: =L9*Parametry!$B$18 -> 37.8 | N9: =M9*IF(F9>0,Parametry!$B$19,1) -> 37.8 | O9: =N9*Parametry!$B$20 -> 75.6 | P9: =H9*(1+0.8+1.2+1.8+2.5) -> 2920 | Q9: řada
A10: Minomet | B10: O | C10: 40 | D10: 0.5 | E10: 1 | F10: 50 | G10: 500 | H10: 220 | I10: 3 | J10: =C10*D10*E10 -> 20 | K10: =IF(H10=0,0,J10/H10) -> 0.090909091 | L10: =J10*Parametry!$B$17 -> 40 | M10: =L10*Parametry!$B$18 -> 56 | N10: =M10*IF(F10>0,Parametry!$B$19,1) -> 84 | O10: =N10*Parametry!$B$20 -> 168 | P10: =H10*(1+0.8+1.2+1.8+2.5) -> 1606
A11: Katapult (ledničky) | B11: O fyzický | C11: 120 | D11: 0.2 | E11: 1 | F11: 40 | G11: 550 | H11: 350 | I11: 6 | J11: =C11*D11*E11 -> 24 | K11: =IF(H11=0,0,J11/H11) -> 0.068571429 | L11: =J11*Parametry!$B$17 -> 48 | M11: =L11*Parametry!$B$18 -> 67.2 | N11: =M11*IF(F11>0,Parametry!$B$19,1) -> 100.8 | O11: =N11*Parametry!$B$20 -> 201.6 | P11: =H11*(1+0.8+1.2+1.8+2.5) -> 2555 | Q11: + rozmáčknutí
A12: Babka s hrncem | B12: O | C12: 25 | D12: 0.7 | E12: 1 | F12: 35 | G12: 150 | H12: 80 | I12: 0 | J12: =C12*D12*E12 -> 17.5 | K12: =IF(H12=0,0,J12/H12) -> 0.21875 | L12: =J12*Parametry!$B$17 -> 35 | M12: =L12*Parametry!$B$18 -> 49 | N12: =M12*IF(F12>0,Parametry!$B$19,1) -> 73.5 | O12: =N12*Parametry!$B$20 -> 147 | P12: =H12*(1+0.8+1.2+1.8+2.5) -> 584
A13: Ohňostroj | B13: O náhodný | C13: 15 | D13: 3 | E13: 1 | F13: 25 | G13: 450 | H13: 60 | I13: 0 | J13: =C13*D13*E13 -> 45 | K13: =IF(H13=0,0,J13/H13) -> 0.75 | L13: =J13*Parametry!$B$17 -> 90 | M13: =L13*Parametry!$B$18 -> 126 | N13: =M13*IF(F13>0,Parametry!$B$19,1) -> 189 | O13: =N13*Parametry!$B$20 -> 378 | P13: =H13*(1+0.8+1.2+1.8+2.5) -> 438 | Q13: náhodný cíl, reálně ~50 % zásahů
A14: Raketomet | B14: P/naváděné | C14: 80 | D14: 0.4 | E14: 1 | F14: 60 | G14: 500 | H14: 450 | I14: 8 | J14: =C14*D14*E14 -> 32 | K14: =IF(H14=0,0,J14/H14) -> 0.071111111 | L14: =J14*Parametry!$B$17 -> 64 | M14: =L14*Parametry!$B$18 -> 89.6 | N14: =M14*IF(F14>0,Parametry!$B$19,1) -> 134.4 | O14: =N14*Parametry!$B$20 -> 268.8 | P14: =H14*(1+0.8+1.2+1.8+2.5) -> 3285
A15: Trebuchet (kravky) | B15: O | C15: 400 | D15: 0.08 | E15: 1 | F15: 80 | G15: 700 | H15: 900 | I15: 12 | J15: =C15*D15*E15 -> 32 | K15: =IF(H15=0,0,J15/H15) -> 0.035555556 | L15: =J15*Parametry!$B$17 -> 64 | M15: =L15*Parametry!$B$18 -> 89.6 | N15: =M15*IF(F15>0,Parametry!$B$19,1) -> 134.4 | O15: =N15*Parametry!$B$20 -> 268.8 | P15: =H15*(1+0.8+1.2+1.8+2.5) -> 6570
A16: Holub s granáty | B16: L | C16: 20 | D16: 1 | E16: 1 | F16: 30 | G16: 0 | H16: 120 | I16: 0 | J16: =C16*D16*E16 -> 20 | K16: =IF(H16=0,0,J16/H16) -> 0.16666667 | L16: =J16*Parametry!$B$17 -> 40 | M16: =L16*Parametry!$B$18 -> 56 | N16: =M16*IF(F16>0,Parametry!$B$19,1) -> 84 | O16: =N16*Parametry!$B$20 -> 168 | P16: =H16*(1+0.8+1.2+1.8+2.5) -> 876 | Q16: letí 3 s
A17: Rogalo | B17: L | C17: 60 | D17: 0.5 | E17: 1 | F17: 45 | G17: 0 | H17: 300 | I17: 0 | J17: =C17*D17*E17 -> 30 | K17: =IF(H17=0,0,J17/H17) -> 0.1 | L17: =J17*Parametry!$B$17 -> 60 | M17: =L17*Parametry!$B$18 -> 84 | N17: =M17*IF(F17>0,Parametry!$B$19,1) -> 126 | O17: =N17*Parametry!$B$20 -> 252 | P17: =H17*(1+0.8+1.2+1.8+2.5) -> 2190 | Q17: letí 5 s
A18: Balón se sudy | B18: L | C18: 150 | D18: 0.2 | E18: 1 | F18: 70 | G18: 0 | H18: 500 | I18: 0 | J18: =C18*D18*E18 -> 30 | K18: =IF(H18=0,0,J18/H18) -> 0.06 | L18: =J18*Parametry!$B$17 -> 60 | M18: =L18*Parametry!$B$18 -> 84 | N18: =M18*IF(F18>0,Parametry!$B$19,1) -> 126 | O18: =N18*Parametry!$B$20 -> 252 | P18: =H18*(1+0.8+1.2+1.8+2.5) -> 3650 | Q18: letí 8 s
A19: Rotační kulomet na šipky | B19: P | C19: 3 | D19: 12 | E19: 1 | F19: 0 | G19: 280 | H19: 280 | I19: 2 | J19: =C19*D19*E19 -> 36 | K19: =IF(H19=0,0,J19/H19) -> 0.12857143 | L19: =J19*Parametry!$B$17 -> 72 | M19: =L19*Parametry!$B$18 -> 100.8 | N19: =M19*IF(F19>0,Parametry!$B$19,1) -> 100.8 | O19: =N19*Parametry!$B$20 -> 201.6 | P19: =H19*(1+0.8+1.2+1.8+2.5) -> 2044 | Q19: roztáčení 1,5 s, zpomaluje
A20: Hasičská stříkačka na hnůj | B20: P proud | C20: 3 | D20: 1 | E20: 1 | F20: 30 | G20: 200 | H20: 180 | I20: 1 | J20: =C20*D20*E20 -> 3 | K20: =IF(H20=0,0,J20/H20) -> 0.016666667 | L20: =J20*Parametry!$B$17 -> 6 | M20: =L20*Parametry!$B$18 -> 8.4 | N20: =M20*IF(F20>0,Parametry!$B$19,1) -> 12.6 | O20: =N20*Parametry!$B$20 -> 25.2 | P20: =H20*(1+0.8+1.2+1.8+2.5) -> 1314 | Q20: dmg je DoT, hlavně odhazuje a lepí
A21: Vrhač včelích úlů | B21: O | C21: 8 | D21: 0.4 | E21: 1 | F21: 60 | G21: 350 | H21: 220 | I21: 1 | J21: =C21*D21*E21 -> 3.2 | K21: =IF(H21=0,0,J21/H21) -> 0.014545455 | L21: =J21*Parametry!$B$17 -> 6.4 | M21: =L21*Parametry!$B$18 -> 8.96 | N21: =M21*IF(F21>0,Parametry!$B$19,1) -> 13.44 | O21: =N21*Parametry!$B$20 -> 26.88 | P21: =H21*(1+0.8+1.2+1.8+2.5) -> 1606 | Q21: roj 5 s = dmg × 5 s trvání
A22: Kanón na kapustu | B22: O | C22: 6 | D22: 0.8 | E22: 6 | F22: 20 | G22: 400 | H22: 150 | I22: 2 | J22: =C22*D22*E22 -> 28.8 | K22: =IF(H22=0,0,J22/H22) -> 0.192 | L22: =J22*Parametry!$B$17 -> 57.6 | M22: =L22*Parametry!$B$18 -> 80.64 | N22: =M22*IF(F22>0,Parametry!$B$19,1) -> 120.96 | O22: =N22*Parametry!$B$20 -> 241.92 | P22: =H22*(1+0.8+1.2+1.8+2.5) -> 1095 | Q22: 6 kusů, malý splash každý
A23: Střílna s dědou | B23: P | C23: 20 | D23: 0.8 | E23: 1 | F23: 0 | G23: 350 | H23: 200 | I23: 1 | J23: =C23*D23*E23 -> 16 | K23: =IF(H23=0,0,J23/H23) -> 0.08 | L23: =J23*Parametry!$B$17 -> 32 | M23: =L23*Parametry!$B$18 -> 44.8 | N23: =M23*IF(F23>0,Parametry!$B$19,1) -> 44.8 | O23: =N23*Parametry!$B$20 -> 89.6 | P23: =H23*(1+0.8+1.2+1.8+2.5) -> 1460 | Q23: +5 % dmg za přežitou vlnu
A24: Zrcadlový periskop | B24: P | C24: 18 | D24: 0.7 | E24: 1 | F24: 0 | G24: 300 | H24: 160 | I24: 0 | J24: =C24*D24*E24 -> 12.6 | K24: =IF(H24=0,0,J24/H24) -> 0.07875 | L24: =J24*Parametry!$B$17 -> 25.2 | M24: =L24*Parametry!$B$18 -> 35.28 | N24: =M24*IF(F24>0,Parametry!$B$19,1) -> 35.28 | O24: =N24*Parametry!$B$20 -> 70.56 | P24: =H24*(1+0.8+1.2+1.8+2.5) -> 1168 | Q24: trefí za štít
A25: Kříž z autobaterií | B25: pasivní | C25: 60 | D25: 0.1 | E25: 1 | F25: 0 | G25: 120 | H25: 140 | I25: 0 | J25: =C25*D25*E25 -> 6 | K25: =IF(H25=0,0,J25/H25) -> 0.042857143 | L25: =J25*Parametry!$B$17 -> 12 | M25: =L25*Parametry!$B$18 -> 16.8 | N25: =M25*IF(F25>0,Parametry!$B$19,1) -> 16.8 | O25: =N25*Parametry!$B$20 -> 33.6 | P25: =H25*(1+0.8+1.2+1.8+2.5) -> 1022 | Q25: 1 výboj za 10 s, jen kov
A26: Dělo na Špekouna | B26: O | C26: 200 | D26: 0.1 | E26: 1 | F26: 90 | G26: 450 | H26: 260 | I26: 5 | J26: =C26*D26*E26 -> 20 | K26: =IF(H26=0,0,J26/H26) -> 0.076923077 | L26: =J26*Parametry!$B$17 -> 40 | M26: =L26*Parametry!$B$18 -> 56 | N26: =M26*IF(F26>0,Parametry!$B$19,1) -> 84 | O26: =N26*Parametry!$B$20 -> 168 | P26: =H26*(1+0.8+1.2+1.8+2.5) -> 1898 | Q26: munice = zabitý Špekoun
A27: Lepidlový minomet | B27: O | C27: 0 | D27: 0.5 | E27: 1 | F27: 60 | G27: 500 | H27: 180 | I27: 3 | J27: =C27*D27*E27 -> 0 | K27: =IF(H27=0,0,J27/H27) -> 0 | L27: =J27*Parametry!$B$17 -> 0 | M27: =L27*Parametry!$B$18 -> 0 | N27: =M27*IF(F27>0,Parametry!$B$19,1) -> 0 | O27: =N27*Parametry!$B$20 -> 0 | P27: =H27*(1+0.8+1.2+1.8+2.5) -> 1314 | Q27: 0 dmg, jen kontrola
... A34: Prak na kočky | B34: O | C34: 6 | D34: 0.6 | E34: 1 | F34: 0 | G34: 300 | H34: 120 | I34: 0 | J34: =C34*D34*E34 -> 3.6 | K34: =IF(H34=0,0,J34/H34) -> 0.03 | L34: =J34*Parametry!$B$17 -> 7.2 | M34: =L34*Parametry!$B$18 -> 10.08 | N34: =M34*IF(F34>0,Parametry!$B$19,1) -> 10.08 | O34: =N34*Parametry!$B$20 -> 20.16 | P34: =H34*(1+0.8+1.2+1.8+2.5) -> 876 | Q34: kočka škrábe 3 s = dmg × 3
A36: DPS L1 = dmg × palba × projektilů (proti jednomu cíli). Splash a DoT zbraně jsou proti davu výrazně silnější — viz list Účinnost a sloupec L4 (dav).
A37: Cena L1–L5 = základ × (1 + 0,8 + 1,2 + 1,8 + 2,5) podle kap. 4.3. Cíl balancu: DPS na 1 prachy má být u drahých zbraní NIŽŠÍ než u levných (platíš za dosah, splash, pohodlí), jinak levné zbraně nemají smysl.
A39: Nejlepší DPS na 1 prachy (L1): | B39: =MAX(K2:K34) -> 0.75
A40: Průměr DPS na 1 prachy (bez podpory): | B40: =SUMIF(K2:K34,">0")/COUNTIF(K2:K34,">0") -> 0.12942139

Sheet Nepřátelé
A1: Nepřítel | B1: HP (základ) | C1: Dmg/s na zeď | D1: Rychlost (pt/s) | E1: Odměna (prachy) | F1: Od vlny | G1: Cíl | H1: Barva (role) | I1: HP na 1 prachy odměny | J1: Poznámka
A2: Loudač | B2: 30 | C2: 4 | D2: 40 | E2: 5 | F2: 1 | G2: zeď | H2: šedá | I2: =IF(E2=0,0,B2/E2) -> 6
A3: Běžec | B3: 15 | C3: 3 | D3: 110 | E3: 4 | F3: 3 | G3: brána | H3: červená | I3: =IF(E3=0,0,B3/E3) -> 3.75 | J3: proběhne past
A4: Boxer | B4: 80 | C4: 15 | D4: 45 | E4: 12 | F4: 3 | G4: brána | H4: červená | I4: =IF(E4=0,0,B4/E4) -> 6.6666667 | J4: 2× vs brána
A5: Štítonoš | B5: 160 | C5: 5 | D5: 35 | E5: 15 | F5: 6 | G5: zeď | H5: šedá | I5: =IF(E5=0,0,B5/E5) -> 10.666667 | J5: 60 + dveře 100, blokuje přímou
A6: Lezec | B6: 40 | C6: 8 | D6: 50 | E6: 14 | F6: 6 | G6: hnízda | H6: žlutá | I6: =IF(E6=0,0,B6/E6) -> 2.8571429 | J6: šplhá
A7: Házeč | B7: 45 | C7: 12 | D7: 40 | E7: 16 | F7: 9 | G7: horní patra | H7: žlutá | I7: =IF(E7=0,0,B7/E7) -> 2.8125 | J7: oblouk
A8: Puškař | B8: 35 | C8: 10 | D8: 35 | E8: 18 | F8: 9 | G8: zbraně | H8: žlutá | I8: =IF(E8=0,0,B8/E8) -> 1.9444444 | J8: z 350 pt
A9: Sebevrah | B9: 25 | C9: 0 | D9: 90 | E9: 20 | F9: 12 | G9: zeď | H9: černá | I9: =IF(E9=0,0,B9/E9) -> 1.25 | J9: 200 splash r 60 na konstrukci
A10: Zloděj | B10: 30 | C10: 0 | D10: 100 | E10: 30 | F10: 12 | G10: brána | H10: modrá | I10: =IF(E10=0,0,B10/E10) -> 1 | J10: krade 15 % prachů
A11: Vozík | B11: 300 | C11: 40 | D11: 30 | E11: 40 | F11: 15 | G11: brána | H11: červená | I11: =IF(E11=0,0,B11/E11) -> 7.5 | J11: 3 tlačiči
A12: Rojnice (30 krys, celkem) | B12: 30 | C12: 30 | D12: 90 | E12: 30 | F12: 15 | G12: vše | H12: šedá | I12: =IF(E12=0,0,B12/E12) -> 1 | J12: 30 × 1 HP
A13: Šaman | B13: 50 | C13: 0 | D13: 40 | E13: 25 | F13: 18 | G13: – | H13: fialová | I13: =IF(E13=0,0,B13/E13) -> 2 | J13: +30 % rychlost okolí
A14: Důchodce s holí | B14: 60 | C14: 4 | D14: 25 | E14: 8 | F14: 4 | G14: zeď | H14: modrá | I14: =IF(E14=0,0,B14/E14) -> 7.5 | J14: ignoruje zpomalení
... A34: Vlk v přestrojení | B34: 60 | C34: 0 | D34: 50 | E34: 30 | F34: 27 | G34: hnízda | H34: žlutá | I34: =IF(E34=0,0,B34/E34) -> 2 | J34: snižuje level
A36: HP a odměny nepřátel z brainstormu (Důchodce dál) jsou odhady — dokument u nich čísla neměl. Cíl: HP na 1 prachy odměny kolem 3–6; vyšší = nepřítel je 'nevýnosný' a hráč ho má důvod nechat pastem.

Sheet Bossové
A1: Boss | B1: HP | C1: Vlna | D1: Odměna | E1: Cíl zabít do (s) | F1: Potřebné DPS (jen boss) | G1: Průraz ×1,5 → DPS | H1: Poznámka
A2: Babička s válečkem | B2: 3000 | C2: 10 | D2: 300 | E2: 60 | F2: =IF(E2=0,0,B2/E2) -> 50 | G2: =F2/1.5 -> 33.333333 | H2: údery = impulz
A3: Traktor | B3: 6000 | C3: 20 | D3: 500 | E3: 75 | F3: =IF(E3=0,0,B3/E3) -> 80 | G3: =F3/1.5 -> 53.333333 | H3: obrněný zepředu
A4: Kolos z ledniček | B4: 8000 | C4: 20 | D4: 600 | E4: 90 | F4: =IF(E4=0,0,B4/E4) -> 88.888889 | G4: =F4/1.5 -> 59.259259 | H4: odpadávají ledničky
A5: Bývalý starosta | B5: 4000 | C5: 10 | D5: 400 | E5: 60 | F5: =IF(E5=0,0,B5/E5) -> 66.666667 | G5: =F5/1.5 -> 44.444444 | H5: omračuje zbraně
A6: Přerostlý kanec | B6: 10000 | C6: 20 | D6: 700 | E6: 100 | F6: =IF(E6=0,0,B6/E6) -> 100 | G6: =F6/1.5 -> 66.666667 | H6: nárazy
A7: Tchyně | B7: 4000 | C7: 10 | D7: 400 | E7: 60 | F7: =IF(E7=0,0,B7/E7) -> 66.666667 | G7: =F7/1.5 -> 44.444444 | H7: brána z beznaděje
A8: Zeppelin z matrací | B8: 5000 | C8: 20 | D8: 500 | E8: 90 | F8: =IF(E8=0,0,B8/E8) -> 55.555556 | G8: =F8/1.5 -> 37.037037 | H8: jen létající + vzduchovka
A9: Dvojčata (2×) | B9: 6000 | C9: 20 | D9: 600 | E9: 90 | F9: =IF(E9=0,0,B9/E9) -> 66.666667 | G9: =F9/1.5 -> 44.444444 | H9: sdílený bar
A10: Ty z minulého běhu | B10: 0 | C10: 20 | D10: 500 | E10: 90 | F10: =IF(E10=0,0,B10/E10) -> 0 | G10: =F10/1.5 -> 0 | H10: HP = tvá bývalá pevnost
A11: Matka všech krys | B11: 7000 | C11: 20 | D11: 600 | E11: 90 | F11: =IF(E11=0,0,B11/E11) -> 77.777778 | G11: =F11/1.5 -> 51.851852 | H11: jen splash
A12: Řetěz (20 Loudačů) | B12: 600 | C12: 10 | D12: 300 | E12: 45 | F12: =IF(E12=0,0,B12/E12) -> 13.333333 | G12: =F12/1.5 -> 8.8888889 | H12: HP = 20 × Loudač × škálování
A13: Soudruh Generalissimus | B13: 5000 | C13: 8 | D13: 500 | E13: 75 | F13: =IF(E13=0,0,B13/E13) -> 66.666667 | G13: =F13/1.5 -> 44.444444 | H13: garda, Gulag, jehly
... A15: Chuchvalec | B15: 40000 | C15: 30 | D15: 2000 | E15: 240 | F15: =IF(E15=0,0,B15/E15) -> 166.66667 | G15: =F15/1.5 -> 111.11111 | H15: srostlina 4 bossů
A17: 'Cíl zabít do' je odhad — nad 60 s je bonus ×1,2 v metě pryč (kap. 20.1). Bossové HP neškálují s vlnou, škáluje jen doprovod.

Sheet Účinnost
A1: Typ dmg \ cíl | B1: Papír/dřevo | C1: Plech/ocel | D1: Grafit | E1: Nepřítel | F1: Boss
A2: Drápání/pěst | B2: 1 | C2: 0.3 | D2: 0.5 | E2: 0 | F2: 0
A3: Oheň | B3: 2 | C3: 0.2 | D3: 0 | E3: 1 | F3: 0.5
A4: Výbuch | B4: 1.5 | C4: 1 | D4: 0.8 | E4: 1.5 | F4: 1
A5: Průraz | B5: 1 | C5: 1 | D5: 1 | E5: 1 | F5: 1.5
A6: Elektřina | B6: 0 | C6: 1.5 | D6: 0 | E6: 1.2 | F6: 0.3
A7: Rozmáčknutí (fyzika) | B7: 0 | C7: 0 | D7: 0 | E7: 1 | F7: 0.2
A9: Dokument kap. 6. Rozmáčknutí: dmg = hmotnost × rychlost × 3 (na nepřátele), násobič pro bosse 0,2. Splash: dmg = base × (1 − d/r)², na vlastní díly × 0,5.
A11: Splash kalkulačka
A12: Základní dmg | B12: 100
A13: Poloměr r | B13: 60
A14: Vzdálenost d | B14: 30
A15: Dmg na nepřítele | B15: =IF(B14>=B13,0,B12*(1-B14/B13)^2) -> 25
A16: Dmg na vlastní díl | B16: =B15*Parametry!$B$21 -> 12.5

Sheet Vlny
A1: Základní počet při první vlně výskytu → | D1: 6 | E1: 3 | F1: 2 | G1: 2 | H1: 2 | I1: 2 | J1: 1 | K1: 1 | L1: 1 | M1: 1 | N1: 1 | O1: 1 | P1: 2 | Q1: 1 | R1: 1 | S1: 2 | T1: 1 | U1: 1 | V1: 1
A2: Od vlny (z listu Nepřátelé) → | D2: =Nepřátelé!$F$2 -> 1 | E2: =Nepřátelé!$F$3 -> 3 | F2: =Nepřátelé!$F$4 -> 3 | G2: =Nepřátelé!$F$5 -> 6 | H2: =Nepřátelé!$F$6 -> 6 | I2: =Nepřátelé!$F$7 -> 9 | J2: =Nepřátelé!$F$8 -> 9 | K2: =Nepřátelé!$F$9 -> 12 | L2: =Nepřátelé!$F$10 -> 12 | M2: =Nepřátelé!$F$11 -> 15 | N2: =Nepřátelé!$F$12 -> 15 | O2: =Nepřátelé!$F$13 -> 18 | P2: =Nepřátelé!$F$14 -> 4 | Q2: =Nepřátelé!$F$15 -> 8 | R2: =Nepřátelé!$F$16 -> 10 | S2: =Nepřátelé!$F$22 -> 7 | T2: =Nepřátelé!$F$24 -> 13 | U2: =Nepřátelé!$F$29 -> 18 | V2: =Nepřátelé!$F$33 -> 26
A3: Vlna | B3: Násobič HP | C3: Násobič počtu | D3: Loudač | E3: Běžec | F3: Boxer | G3: Štítonoš | H3: Lezec | I3: Házeč | J3: Puškař | K3: Sebevrah | L3: Zloděj | M3: Vozík | N3: Rojnice (30 krys, celkem) | O3: Šaman | P3: Důchodce s holí | Q3: Kopáč | R3: Černobylák | S3: Ožrala | T3: Špekoun | U3: Kříženec prasete a motorky | V3: Ex | W3: Nepřátel celkem | X3: HP vlny celkem | Y3: Dmg/s na zeď celkem | Z3: Odměna za nepřátele | AA3: Bonus za vlnu | AB3: Kumulované prachy | AC3: Potřebné DPS (celé) | AD3: Potřebné DPS zbraní | AE3: Koupitelné DPS zbraní | AF3: Poměr koupitelné/potřebné | AG3: Stav | AH3: Boss
A4: 1 | B4: =Parametry!$B$6^(A4-1) -> 1 | C4: =Parametry!$B$7^(A4-1) -> 1 | D4: =IF($A4>=D$2,ROUND(D$1*Parametry!$B$7^($A4-D$2),0),0) -> 6 | E4: =IF($A4>=E$2,ROUND(E$1*Parametry!$B$7^($A4-E$2),0),0) -> 0 | F4: =IF($A4>=F$2,ROUND(F$1*Parametry!$B$7^($A4-F$2),0),0) -> 0 | G4: =IF($A4>=G$2,ROUND(G$1*Parametry!$B$7^($A4-G$2),0),0) -> 0 | H4: =IF($A4>=H$2,ROUND(H$1*Parametry!$B$7^($A4-H$2),0),0) -> 0 | I4: =IF($A4>=I$2,ROUND(I$1*Parametry!$B$7^($A4-I$2),0),0) -> 0 | J4: =IF($A4>=J$2,ROUND(J$1*Parametry!$B$7^($A4-J$2),0),0) -> 0 | K4: =IF($A4>=K$2,ROUND(K$1*Parametry!$B$7^($A4-K$2),0),0) -> 0 | ... V4: =IF($A4>=V$2,ROUND(V$1*Parametry!$B$7^($A4-V$2),0),0) -> 0 | W4: =SUM(D4:V4) -> 6 | X4: =(D4*Nepřátelé!$B$2+E4*Nepřátelé!$B$3+F4*Nepřátelé!$B$4+G4*Nepřátelé!$B$5+H4*Nepřátelé!$B$6+I4*Nepřátelé!$B$7+J4*Nepřátelé!$B$8+K4*Nepřátelé!$B$9+L4*Nepřátelé!$B$10+M4*Nepřátelé!$B$11+N4*Nepřátelé!$B$12+O4*Nepřátelé!$B$13+P4*Nepřátelé!$B$14+Q4*Nepřátelé!$B$15+R4*Nepřátelé!$B$16+S4*Nepřátelé!$B$22+T4*Nepřátelé!$B$24+U4*Nepřátelé!$B$29+V4*Nepřátelé!$B$33)*B4 -> 180 | Y4: =(D4*Nepřátelé!$C$2+E4*Nepřátelé!$C$3+F4*Nepřátelé!$C$4+G4*Nepřátelé!$C$5+H4*Nepřátelé!$C$6+I4*Nepřátelé!$C$7+J4*Nepřátelé!$C$8+K4*Nepřátelé!$C$9+L4*Nepřátelé!$C$10+M4*Nepřátelé!$C$11+N4*Nepřátelé!$C$12+O4*Nepřátelé!$C$13+P4*Nepřátelé!$C$14+Q4*Nepřátelé!$C$15+R4*Nepřátelé!$C$16+S4*Nepřátelé!$C$22+T4*Nepřátelé!$C$24+U4*Nepřátelé!$C$29+V4*Nepřátelé!$C$33) -> 24 | Z4: =(D4*Nepřátelé!$E$2+E4*Nepřátelé!$E$3+F4*Nepřátelé!$E$4+G4*Nepřátelé!$E$5+H4*Nepřátelé!$E$6+I4*Nepřátelé!$E$7+J4*Nepřátelé!$E$8+K4*Nepřátelé!$E$9+L4*Nepřátelé!$E$10+M4*Nepřátelé!$E$11+N4*Nepřátelé!$E$12+O4*Nepřátelé!$E$13+P4*Nepřátelé!$E$14+Q4*Nepřátelé!$E$15+R4*Nepřátelé!$E$16+S4*Nepřátelé!$E$22+T4*Nepřátelé!$E$24+U4*Nepřátelé!$E$29+V4*Nepřátelé!$E$33)*B4^Parametry!$B$12 -> 30 | AA4: =Parametry!$B$14+Parametry!$B$15*A4 -> 25 | AB4: =Parametry!$B$13+Z4+AA4 -> 255 | AC4: =X4/Parametry!$B$8 -> 4 | AD4: =AC4*Parametry!$B$10 -> 2.8 | AE4: =Parametry!$B$13*Parametry!$B$16*Zbraně!$B$40*Parametry!$B$11 -> 9.3183403 | AF4: =IF(AD4=0,0,AE4/AD4) -> 3.3279787 | AG4: =IF(AF4<0.8,"TĚŽKÁ",IF(AF4>2,"LEHKÁ","OK")) -> LEHKÁ
A5: 2 | B5: =Parametry!$B$6^(A5-1) -> 1.15 | C5: =Parametry!$B$7^(A5-1) -> 1.08 | D5: =IF($A5>=D$2,ROUND(D$1*Parametry!$B$7^($A5-D$2),0),0) -> 6 | E5: =IF($A5>=E$2,ROUND(E$1*Parametry!$B$7^($A5-E$2),0),0) -> 0 | F5: =IF($A5>=F$2,ROUND(F$1*Parametry!$B$7^($A5-F$2),0),0) -> 0 | G5: =IF($A5>=G$2,ROUND(G$1*Parametry!$B$7^($A5-G$2),0),0) -> 0 | H5: =IF($A5>=H$2,ROUND(H$1*Parametry!$B$7^($A5-H$2),0),0) -> 0 | I5: =IF($A5>=I$2,ROUND(I$1*Parametry!$B$7^($A5-I$2),0),0) -> 0 | J5: =IF($A5>=J$2,ROUND(J$1*Parametry!$B$7^($A5-J$2),0),0) -> 0 | K5: =IF($A5>=K$2,ROUND(K$1*Parametry!$B$7^($A5-K$2),0),0) -> 0 | ... V5: =IF($A5>=V$2,ROUND(V$1*Parametry!$B$7^($A5-V$2),0),0) -> 0 | W5: =SUM(D5:V5) -> 6 | X5: =(D5*Nepřátelé!$B$2+E5*Nepřátelé!$B$3+F5*Nepřátelé!$B$4+G5*Nepřátelé!$B$5+H5*Nepřátelé!$B$6+I5*Nepřátelé!$B$7+J5*Nepřátelé!$B$8+K5*Nepřátelé!$B$9+L5*Nepřátelé!$B$10+M5*Nepřátelé!$B$11+N5*Nepřátelé!$B$12+O5*Nepřátelé!$B$13+P5*Nepřátelé!$B$14+Q5*Nepřátelé!$B$15+R5*Nepřátelé!$B$16+S5*Nepřátelé!$B$22+T5*Nepřátelé!$B$24+U5*Nepřátelé!$B$29+V5*Nepřátelé!$B$33)*B5 -> 207 | Y5: =(D5*Nepřátelé!$C$2+E5*Nepřátelé!$C$3+F5*Nepřátelé!$C$4+G5*Nepřátelé!$C$5+H5*Nepřátelé!$C$6+I5*Nepřátelé!$C$7+J5*Nepřátelé!$C$8+K5*Nepřátelé!$C$9+L5*Nepřátelé!$C$10+M5*Nepřátelé!$C$11+N5*Nepřátelé!$C$12+O5*Nepřátelé!$C$13+P5*Nepřátelé!$C$14+Q5*Nepřátelé!$C$15+R5*Nepřátelé!$C$16+S5*Nepřátelé!$C$22+T5*Nepřátelé!$C$24+U5*Nepřátelé!$C$29+V5*Nepřátelé!$C$33) -> 24 | Z5: =(D5*Nepřátelé!$E$2+E5*Nepřátelé!$E$3+F5*Nepřátelé!$E$4+G5*Nepřátelé!$E$5+H5*Nepřátelé!$E$6+I5*Nepřátelé!$E$7+J5*Nepřátelé!$E$8+K5*Nepřátelé!$E$9+L5*Nepřátelé!$E$10+M5*Nepřátelé!$E$11+N5*Nepřátelé!$E$12+O5*Nepřátelé!$E$13+P5*Nepřátelé!$E$14+Q5*Nepřátelé!$E$15+R5*Nepřátelé!$E$16+S5*Nepřátelé!$E$22+T5*Nepřátelé!$E$24+U5*Nepřátelé!$E$29+V5*Nepřátelé!$E$33)*B5^Parametry!$B$12 -> 33.08337 | AA5: =Parametry!$B$14+Parametry!$B$15*A5 -> 30 | AB5: =AB4+Z5+AA5 -> 318.08337 | AC5: =X5/Parametry!$B$8 -> 4.6 | AD5: =AC5*Parametry!$B$10 -> 3.22 | AE5: =AB4*Parametry!$B$16*Zbraně!$B$40*Parametry!$B$11 -> 11.880884 | AF5: =IF(AD5=0,0,AE5/AD5) -> 3.6897155 | AG5: =IF(AF5<0.8,"TĚŽKÁ",IF(AF5>2,"LEHKÁ","OK")) -> LEHKÁ
A6: 3 | B6: =Parametry!$B$6^(A6-1) -> 1.3225 | C6: =Parametry!$B$7^(A6-1) -> 1.1664 | D6: =IF($A6>=D$2,ROUND(D$1*Parametry!$B$7^($A6-D$2),0),0) -> 7 | E6: =IF($A6>=E$2,ROUND(E$1*Parametry!$B$7^($A6-E$2),0),0) -> 3 | F6: =IF($A6>=F$2,ROUND(F$1*Parametry!$B$7^($A6-F$2),0),0) -> 2 | G6: =IF($A6>=G$2,ROUND(G$1*Parametry!$B$7^($A6-G$2),0),0) -> 0 | H6: =IF($A6>=H$2,ROUND(H$1*Parametry!$B$7^($A6-H$2),0),0) -> 0 | I6: =IF($A6>=I$2,ROUND(I$1*Parametry!$B$7^($A6-I$2),0),0) -> 0 | J6: =IF($A6>=J$2,ROUND(J$1*Parametry!$B$7^($A6-J$2),0),0) -> 0 | K6: =IF($A6>=K$2,ROUND(K$1*Parametry!$B$7^($A6-K$2),0),0) -> 0 | ... V6: =IF($A6>=V$2,ROUND(V$1*Parametry!$B$7^($A6-V$2),0),0) -> 0 | W6: =SUM(D6:V6) -> 12 | X6: =(D6*Nepřátelé!$B$2+E6*Nepřátelé!$B$3+F6*Nepřátelé!$B$4+G6*Nepřátelé!$B$5+H6*Nepřátelé!$B$6+I6*Nepřátelé!$B$7+J6*Nepřátelé!$B$8+K6*Nepřátelé!$B$9+L6*Nepřátelé!$B$10+M6*Nepřátelé!$B$11+N6*Nepřátelé!$B$12+O6*Nepřátelé!$B$13+P6*Nepřátelé!$B$14+Q6*Nepřátelé!$B$15+R6*Nepřátelé!$B$16+S6*Nepřátelé!$B$22+T6*Nepřátelé!$B$24+U6*Nepřátelé!$B$29+V6*Nepřátelé!$B$33)*B6 -> 548.8375 | Y6: =(D6*Nepřátelé!$C$2+E6*Nepřátelé!$C$3+F6*Nepřátelé!$C$4+G6*Nepřátelé!$C$5+H6*Nepřátelé!$C$6+I6*Nepřátelé!$C$7+J6*Nepřátelé!$C$8+K6*Nepřátelé!$C$9+L6*Nepřátelé!$C$10+M6*Nepřátelé!$C$11+N6*Nepřátelé!$C$12+O6*Nepřátelé!$C$13+P6*Nepřátelé!$C$14+Q6*Nepřátelé!$C$15+R6*Nepřátelé!$C$16+S6*Nepřátelé!$C$22+T6*Nepřátelé!$C$24+U6*Nepřátelé!$C$29+V6*Nepřátelé!$C$33) -> 67 | Z6: =(D6*Nepřátelé!$E$2+E6*Nepřátelé!$E$3+F6*Nepřátelé!$E$4+G6*Nepřátelé!$E$5+H6*Nepřátelé!$E$6+I6*Nepřátelé!$E$7+J6*Nepřátelé!$E$8+K6*Nepřátelé!$E$9+L6*Nepřátelé!$E$10+M6*Nepřátelé!$E$11+N6*Nepřátelé!$E$12+O6*Nepřátelé!$E$13+P6*Nepřátelé!$E$14+Q6*Nepřátelé!$E$15+R6*Nepřátelé!$E$16+S6*Nepřátelé!$E$22+T6*Nepřátelé!$E$24+U6*Nepřátelé!$E$29+V6*Nepřátelé!$E$33)*B6^Parametry!$B$12 -> 86.344628 | AA6: =Parametry!$B$14+Parametry!$B$15*A6 -> 35 | AB6: =AB5+Z6+AA6 -> 439.428 | AC6: =X6/Parametry!$B$8 -> 12.196389 | AD6: =AC6*Parametry!$B$10 -> 8.5374722 | AE6: =AB5*Parametry!$B$16*Zbraně!$B$40*Parametry!$B$11 -> 14.820045 | AF6: =IF(AD6=0,0,AE6/AD6) -> 1.7358821 | AG6: =IF(AF6<0.8,"TĚŽKÁ",IF(AF6>2,"LEHKÁ","OK")) -> OK
A7: 4 | B7: =Parametry!$B$6^(A7-1) -> 1.520875 | C7: =Parametry!$B$7^(A7-1) -> 1.259712 | D7: =IF($A7>=D$2,ROUND(D$1*Parametry!$B$7^($A7-D$2),0),0) -> 8 | E7: =IF($A7>=E$2,ROUND(E$1*Parametry!$B$7^($A7-E$2),0),0) -> 3 | F7: =IF($A7>=F$2,ROUND(F$1*Parametry!$B$7^($A7-F$2),0),0) -> 2 | G7: =IF($A7>=G$2,ROUND(G$1*Parametry!$B$7^($A7-G$2),0),0) -> 0 | H7: =IF($A7>=H$2,ROUND(H$1*Parametry!$B$7^($A7-H$2),0),0) -> 0 | I7: =IF($A7>=I$2,ROUND(I$1*Parametry!$B$7^($A7-I$2),0),0) -> 0 | J7: =IF($A7>=J$2,ROUND(J$1*Parametry!$B$7^($A7-J$2),0),0) -> 0 | K7: =IF($A7>=K$2,ROUND(K$1*Parametry!$B$7^($A7-K$2),0),0) -> 0 | ... V7: =IF($A7>=V$2,ROUND(V$1*Parametry!$B$7^($A7-V$2),0),0) -> 0 | W7: =SUM(D7:V7) -> 15 | X7: =(D7*Nepřátelé!$B$2+E7*Nepřátelé!$B$3+F7*Nepřátelé!$B$4+G7*Nepřátelé!$B$5+H7*Nepřátelé!$B$6+I7*Nepřátelé!$B$7+J7*Nepřátelé!$B$8+K7*Nepřátelé!$B$9+L7*Nepřátelé!$B$10+M7*Nepřátelé!$B$11+N7*Nepřátelé!$B$12+O7*Nepřátelé!$B$13+P7*Nepřátelé!$B$14+Q7*Nepřátelé!$B$15+R7*Nepřátelé!$B$16+S7*Nepřátelé!$B$22+T7*Nepřátelé!$B$24+U7*Nepřátelé!$B$29+V7*Nepřátelé!$B$33)*B7 -> 859.29437 | Y7: =(D7*Nepřátelé!$C$2+E7*Nepřátelé!$C$3+F7*Nepřátelé!$C$4+G7*Nepřátelé!$C$5+H7*Nepřátelé!$C$6+I7*Nepřátelé!$C$7+J7*Nepřátelé!$C$8+K7*Nepřátelé!$C$9+L7*Nepřátelé!$C$10+M7*Nepřátelé!$C$11+N7*Nepřátelé!$C$12+O7*Nepřátelé!$C$13+P7*Nepřátelé!$C$14+Q7*Nepřátelé!$C$15+R7*Nepřátelé!$C$16+S7*Nepřátelé!$C$22+T7*Nepřátelé!$C$24+U7*Nepřátelé!$C$29+V7*Nepřátelé!$C$33) -> 79 | Z7: =(D7*Nepřátelé!$E$2+E7*Nepřátelé!$E$3+F7*Nepřátelé!$E$4+G7*Nepřátelé!$E$5+H7*Nepřátelé!$E$6+I7*Nepřátelé!$E$7+J7*Nepřátelé!$E$8+K7*Nepřátelé!$E$9+L7*Nepřátelé!$E$10+M7*Nepřátelé!$E$11+N7*Nepřátelé!$E$12+O7*Nepřátelé!$E$13+P7*Nepřátelé!$E$14+Q7*Nepřátelé!$E$15+R7*Nepřátelé!$E$16+S7*Nepřátelé!$E$22+T7*Nepřátelé!$E$24+U7*Nepřátelé!$E$29+V7*Nepřátelé!$E$33)*B7^Parametry!$B$12 -> 123.38242 | AA7: =Parametry!$B$14+Parametry!$B$15*A7 -> 40 | AB7: =AB6+Z7+AA7 -> 602.81042 | AC7: =X7/Parametry!$B$8 -> 19.095431 | AD7: =AC7*Parametry!$B$10 -> 13.366801 | AE7: =AB6*Parametry!$B$16*Zbraně!$B$40*Parametry!$B$11 -> 20.473698 | AF7: =IF(AD7=0,0,AE7/AD7) -> 1.5316827 | AG7: =IF(AF7<0.8,"TĚŽKÁ",IF(AF7>2,"LEHKÁ","OK")) -> OK
A8: 5 | B8: =Parametry!$B$6^(A8-1) -> 1.7490063 | C8: =Parametry!$B$7^(A8-1) -> 1.360489 | D8: =IF($A8>=D$2,ROUND(D$1*Parametry!$B$7^($A8-D$2),0),0) -> 8 | E8: =IF($A8>=E$2,ROUND(E$1*Parametry!$B$7^($A8-E$2),0),0) -> 3 | F8: =IF($A8>=F$2,ROUND(F$1*Parametry!$B$7^($A8-F$2),0),0) -> 2 | G8: =IF($A8>=G$2,ROUND(G$1*Parametry!$B$7^($A8-G$2),0),0) -> 0 | H8: =IF($A8>=H$2,ROUND(H$1*Parametry!$B$7^($A8-H$2),0),0) -> 0 | I8: =IF($A8>=I$2,ROUND(I$1*Parametry!$B$7^($A8-I$2),0),0) -> 0 | J8: =IF($A8>=J$2,ROUND(J$1*Parametry!$B$7^($A8-J$2),0),0) -> 0 | K8: =IF($A8>=K$2,ROUND(K$1*Parametry!$B$7^($A8-K$2),0),0) -> 0 | ... V8: =IF($A8>=V$2,ROUND(V$1*Parametry!$B$7^($A8-V$2),0),0) -> 0 | W8: =SUM(D8:V8) -> 15 | X8: =(D8*Nepřátelé!$B$2+E8*Nepřátelé!$B$3+F8*Nepřátelé!$B$4+G8*Nepřátelé!$B$5+H8*Nepřátelé!$B$6+I8*Nepřátelé!$B$7+J8*Nepřátelé!$B$8+K8*Nepřátelé!$B$9+L8*Nepřátelé!$B$10+M8*Nepřátelé!$B$11+N8*Nepřátelé!$B$12+O8*Nepřátelé!$B$13+P8*Nepřátelé!$B$14+Q8*Nepřátelé!$B$15+R8*Nepřátelé!$B$16+S8*Nepřátelé!$B$22+T8*Nepřátelé!$B$24+U8*Nepřátelé!$B$29+V8*Nepřátelé!$B$33)*B8 -> 988.18853 | Y8: =(D8*Nepřátelé!$C$2+E8*Nepřátelé!$C$3+F8*Nepřátelé!$C$4+G8*Nepřátelé!$C$5+H8*Nepřátelé!$C$6+I8*Nepřátelé!$C$7+J8*Nepřátelé!$C$8+K8*Nepřátelé!$C$9+L8*Nepřátelé!$C$10+M8*Nepřátelé!$C$11+N8*Nepřátelé!$C$12+O8*Nepřátelé!$C$13+P8*Nepřátelé!$C$14+Q8*Nepřátelé!$C$15+R8*Nepřátelé!$C$16+S8*Nepřátelé!$C$22+T8*Nepřátelé!$C$24+U8*Nepřátelé!$C$29+V8*Nepřátelé!$C$33) -> 79 | Z8: =(D8*Nepřátelé!$E$2+E8*Nepřátelé!$E$3+F8*Nepřátelé!$E$4+G8*Nepřátelé!$E$5+H8*Nepřátelé!$E$6+I8*Nepřátelé!$E$7+J8*Nepřátelé!$E$8+K8*Nepřátelé!$E$9+L8*Nepřátelé!$E$10+M8*Nepřátelé!$E$11+N8*Nepřátelé!$E$12+O8*Nepřátelé!$E$13+P8*Nepřátelé!$E$14+Q8*Nepřátelé!$E$15+R8*Nepřátelé!$E$16+S8*Nepřátelé!$E$22+T8*Nepřátelé!$E$24+U8*Nepřátelé!$E$29+V8*Nepřátelé!$E$33)*B8^Parametry!$B$12 -> 136.06354 | AA8: =Parametry!$B$14+Parametry!$B$15*A8 -> 45 | AB8: =AB7+Z8+AA8 -> 783.87397 | AC8: =X8/Parametry!$B$8 -> 21.959745 | AD8: =AC8*Parametry!$B$10 -> 15.371822 | AE8: =AB7*Parametry!$B$16*Zbraně!$B$40*Parametry!$B$11 -> 28.085963 | AF8: =IF(AD8=0,0,AE8/AD8) -> 1.827107 | AG8: =IF(AF8<0.8,"TĚŽKÁ",IF(AF8>2,"LEHKÁ","OK")) -> OK
A9: 6 | B9: =Parametry!$B$6^(A9-1) -> 2.0113572 | C9: =Parametry!$B$7^(A9-1) -> 1.4693281 | D9: =IF($A9>=D$2,ROUND(D$1*Parametry!$B$7^($A9-D$2),0),0) -> 9 | E9: =IF($A9>=E$2,ROUND(E$1*Parametry!$B$7^($A9-E$2),0),0) -> 4 | F9: =IF($A9>=F$2,ROUND(F$1*Parametry!$B$7^($A9-F$2),0),0) -> 3 | G9: =IF($A9>=G$2,ROUND(G$1*Parametry!$B$7^($A9-G$2),0),0) -> 2 | H9: =IF($A9>=H$2,ROUND(H$1*Parametry!$B$7^($A9-H$2),0),0) -> 2 | I9: =IF($A9>=I$2,ROUND(I$1*Parametry!$B$7^($A9-I$2),0),0) -> 0 | J9: =IF($A9>=J$2,ROUND(J$1*Parametry!$B$7^($A9-J$2),0),0) -> 0 | K9: =IF($A9>=K$2,ROUND(K$1*Parametry!$B$7^($A9-K$2),0),0) -> 0 | ... V9: =IF($A9>=V$2,ROUND(V$1*Parametry!$B$7^($A9-V$2),0),0) -> 0 | W9: =SUM(D9:V9) -> 22 | X9: =(D9*Nepřátelé!$B$2+E9*Nepřátelé!$B$3+F9*Nepřátelé!$B$4+G9*Nepřátelé!$B$5+H9*Nepřátelé!$B$6+I9*Nepřátelé!$B$7+J9*Nepřátelé!$B$8+K9*Nepřátelé!$B$9+L9*Nepřátelé!$B$10+M9*Nepřátelé!$B$11+N9*Nepřátelé!$B$12+O9*Nepřátelé!$B$13+P9*Nepřátelé!$B$14+Q9*Nepřátelé!$B$15+R9*Nepřátelé!$B$16+S9*Nepřátelé!$B$22+T9*Nepřátelé!$B$24+U9*Nepřátelé!$B$29+V9*Nepřátelé!$B$33)*B9 -> 2192.3793 | Y9: =(D9*Nepřátelé!$C$2+E9*Nepřátelé!$C$3+F9*Nepřátelé!$C$4+G9*Nepřátelé!$C$5+H9*Nepřátelé!$C$6+I9*Nepřátelé!$C$7+J9*Nepřátelé!$C$8+K9*Nepřátelé!$C$9+L9*Nepřátelé!$C$10+M9*Nepřátelé!$C$11+N9*Nepřátelé!$C$12+O9*Nepřátelé!$C$13+P9*Nepřátelé!$C$14+Q9*Nepřátelé!$C$15+R9*Nepřátelé!$C$16+S9*Nepřátelé!$C$22+T9*Nepřátelé!$C$24+U9*Nepřátelé!$C$29+V9*Nepřátelé!$C$33) -> 127 | Z9: =(D9*Nepřátelé!$E$2+E9*Nepřátelé!$E$3+F9*Nepřátelé!$E$4+G9*Nepřátelé!$E$5+H9*Nepřátelé!$E$6+I9*Nepřátelé!$E$7+J9*Nepřátelé!$E$8+K9*Nepřátelé!$E$9+L9*Nepřátelé!$E$10+M9*Nepřátelé!$E$11+N9*Nepřátelé!$E$12+O9*Nepřátelé!$E$13+P9*Nepřátelé!$E$14+Q9*Nepřátelé!$E$15+R9*Nepřátelé!$E$16+S9*Nepřátelé!$E$22+T9*Nepřátelé!$E$24+U9*Nepřátelé!$E$29+V9*Nepřátelé!$E$33)*B9^Parametry!$B$12 -> 278.8936 | AA9: =Parametry!$B$14+Parametry!$B$15*A9 -> 50 | AB9: =AB8+Z9+AA9 -> 1112.7676 | AC9: =X9/Parametry!$B$8 -> 48.719541 | AD9: =AC9*Parametry!$B$10 -> 34.103679 | AE9: =AB8*Parametry!$B$16*Zbraně!$B$40*Parametry!$B$11 -> 36.522022 | AF9: =IF(AD9=0,0,AE9/AD9) -> 1.0709115 | AG9: =IF(AF9<0.8,"TĚŽKÁ",IF(AF9>2,"LEHKÁ","OK")) -> OK
A10: 7 | B10: =Parametry!$B$6^(A10-1) -> 2.3130608 | C10: =Parametry!$B$7^(A10-1) -> 1.5868743 | D10: =IF($A10>=D$2,ROUND(D$1*Parametry!$B$7^($A10-D$2),0),0) -> 10 | E10: =IF($A10>=E$2,ROUND(E$1*Parametry!$B$7^($A10-E$2),0),0) -> 4 | F10: =IF($A10>=F$2,ROUND(F$1*Parametry!$B$7^($A10-F$2),0),0) -> 3 | G10: =IF($A10>=G$2,ROUND(G$1*Parametry!$B$7^($A10-G$2),0),0) -> 2 | H10: =IF($A10>=H$2,ROUND(H$1*Parametry!$B$7^($A10-H$2),0),0) -> 2 | I10: =IF($A10>=I$2,ROUND(I$1*Parametry!$B$7^($A10-I$2),0),0) -> 0 | J10: =IF($A10>=J$2,ROUND(J$1*Parametry!$B$7^($A10-J$2),0),0) -> 0 | K10: =IF($A10>=K$2,ROUND(K$1*Parametry!$B$7^($A10-K$2),0),0) -> 0 | ... V10: =IF($A10>=V$2,ROUND(V$1*Parametry!$B$7^($A10-V$2),0),0) -> 0 | W10: =SUM(D10:V10) -> 26 | X10: =(D10*Nepřátelé!$B$2+E10*Nepřátelé!$B$3+F10*Nepřátelé!$B$4+G10*Nepřátelé!$B$5+H10*Nepřátelé!$B$6+I10*Nepřátelé!$B$7+J10*Nepřátelé!$B$8+K10*Nepřátelé!$B$9+L10*Nepřátelé!$B$10+M10*Nepřátelé!$B$11+N10*Nepřátelé!$B$12+O10*Nepřátelé!$B$13+P10*Nepřátelé!$B$14+Q10*Nepřátelé!$B$15+R10*Nepřátelé!$B$16+S10*Nepřátelé!$B$22+T10*Nepřátelé!$B$24+U10*Nepřátelé!$B$29+V10*Nepřátelé!$B$33)*B10 -> 2937.5872 | Y10: =(D10*Nepřátelé!$C$2+E10*Nepřátelé!$C$3+F10*Nepřátelé!$C$4+G10*Nepřátelé!$C$5+H10*Nepřátelé!$C$6+I10*Nepřátelé!$C$7+J10*Nepřátelé!$C$8+K10*Nepřátelé!$C$9+L10*Nepřátelé!$C$10+M10*Nepřátelé!$C$11+N10*Nepřátelé!$C$12+O10*Nepřátelé!$C$13+P10*Nepřátelé!$C$14+Q10*Nepřátelé!$C$15+R10*Nepřátelé!$C$16+S10*Nepřátelé!$C$22+T10*Nepřátelé!$C$24+U10*Nepřátelé!$C$29+V10*Nepřátelé!$C$33) -> 145 | Z10: =(D10*Nepřátelé!$E$2+E10*Nepřátelé!$E$3+F10*Nepřátelé!$E$4+G10*Nepřátelé!$E$5+H10*Nepřátelé!$E$6+I10*Nepřátelé!$E$7+J10*Nepřátelé!$E$8+K10*Nepřátelé!$E$9+L10*Nepřátelé!$E$10+M10*Nepřátelé!$E$11+N10*Nepřátelé!$E$12+O10*Nepřátelé!$E$13+P10*Nepřátelé!$E$14+Q10*Nepřátelé!$E$15+R10*Nepřátelé!$E$16+S10*Nepřátelé!$E$22+T10*Nepřátelé!$E$24+U10*Nepřátelé!$E$29+V10*Nepřátelé!$E$33)*B10^Parametry!$B$12 -> 374.10565 | AA10: =Parametry!$B$14+Parametry!$B$15*A10 -> 55 | AB10: =AB9+Z10+AA10 -> 1541.8732 | AC10: =X10/Parametry!$B$8 -> 65.279715 | AD10: =AC10*Parametry!$B$10 -> 45.6958 | AE10: =AB9*Parametry!$B$16*Zbraně!$B$40*Parametry!$B$11 -> 51.845734 | AF10: =IF(AD10=0,0,AE10/AD10) -> 1.1345842 | AG10: =IF(AF10<0.8,"TĚŽKÁ",IF(AF10>2,"LEHKÁ","OK")) -> OK
A11: 8 | B11: =Parametry!$B$6^(A11-1) -> 2.6600199 | C11: =Parametry!$B$7^(A11-1) -> 1.7138243 | D11: =IF($A11>=D$2,ROUND(D$1*Parametry!$B$7^($A11-D$2),0),0) -> 10 | E11: =IF($A11>=E$2,ROUND(E$1*Parametry!$B$7^($A11-E$2),0),0) -> 4 | F11: =IF($A11>=F$2,ROUND(F$1*Parametry!$B$7^($A11-F$2),0),0) -> 3 | G11: =IF($A11>=G$2,ROUND(G$1*Parametry!$B$7^($A11-G$2),0),0) -> 2 | H11: =IF($A11>=H$2,ROUND(H$1*Parametry!$B$7^($A11-H$2),0),0) -> 2 | I11: =IF($A11>=I$2,ROUND(I$1*Parametry!$B$7^($A11-I$2),0),0) -> 0 | J11: =IF($A11>=J$2,ROUND(J$1*Parametry!$B$7^($A11-J$2),0),0) -> 0 | K11: =IF($A11>=K$2,ROUND(K$1*Parametry!$B$7^($A11-K$2),0),0) -> 0 | ... V11: =IF($A11>=V$2,ROUND(V$1*Parametry!$B$7^($A11-V$2),0),0) -> 0 | W11: =SUM(D11:V11) -> 27 | X11: =(D11*Nepřátelé!$B$2+E11*Nepřátelé!$B$3+F11*Nepřátelé!$B$4+G11*Nepřátelé!$B$5+H11*Nepřátelé!$B$6+I11*Nepřátelé!$B$7+J11*Nepřátelé!$B$8+K11*Nepřátelé!$B$9+L11*Nepřátelé!$B$10+M11*Nepřátelé!$B$11+N11*Nepřátelé!$B$12+O11*Nepřátelé!$B$13+P11*Nepřátelé!$B$14+Q11*Nepřátelé!$B$15+R11*Nepřátelé!$B$16+S11*Nepřátelé!$B$22+T11*Nepřátelé!$B$24+U11*Nepřátelé!$B$29+V11*Nepřátelé!$B$33)*B11 -> 3564.4266 | Y11: =(D11*Nepřátelé!$C$2+E11*Nepřátelé!$C$3+F11*Nepřátelé!$C$4+G11*Nepřátelé!$C$5+H11*Nepřátelé!$C$6+I11*Nepřátelé!$C$7+J11*Nepřátelé!$C$8+K11*Nepřátelé!$C$9+L11*Nepřátelé!$C$10+M11*Nepřátelé!$C$11+N11*Nepřátelé!$C$12+O11*Nepřátelé!$C$13+P11*Nepřátelé!$C$14+Q11*Nepřátelé!$C$15+R11*Nepřátelé!$C$16+S11*Nepřátelé!$C$22+T11*Nepřátelé!$C$24+U11*Nepřátelé!$C$29+V11*Nepřátelé!$C$33) -> 151 | Z11: =(D11*Nepřátelé!$E$2+E11*Nepřátelé!$E$3+F11*Nepřátelé!$E$4+G11*Nepřátelé!$E$5+H11*Nepřátelé!$E$6+I11*Nepřátelé!$E$7+J11*Nepřátelé!$E$8+K11*Nepřátelé!$E$9+L11*Nepřátelé!$E$10+M11*Nepřátelé!$E$11+N11*Nepřátelé!$E$12+O11*Nepřátelé!$E$13+P11*Nepřátelé!$E$14+Q11*Nepřátelé!$E$15+R11*Nepřátelé!$E$16+S11*Nepřátelé!$E$22+T11*Nepřátelé!$E$24+U11*Nepřátelé!$E$29+V11*Nepřátelé!$E$33)*B11^Parametry!$B$12 -> 448.2578 | AA11: =Parametry!$B$14+Parametry!$B$15*A11 -> 60 | AB11: =AB10+Z11+AA11 -> 2050.131 | AC11: =X11/Parametry!$B$8 -> 79.209481 | AD11: =AC11*Parametry!$B$10 -> 55.446637 | AE11: =AB10*Parametry!$B$16*Zbraně!$B$40*Parametry!$B$11 -> 71.838497 | AF11: =IF(AD11=0,0,AE11/AD11) -> 1.2956331 | AG11: =IF(AF11<0.8,"TĚŽKÁ",IF(AF11>2,"LEHKÁ","OK")) -> OK | AH11: Soudruh
A12: 9 | B12: =Parametry!$B$6^(A12-1) -> 3.0590229 | C12: =Parametry!$B$7^(A12-1) -> 1.8509302 | D12: =IF($A12>=D$2,ROUND(D$1*Parametry!$B$7^($A12-D$2),0),0) -> 11 | E12: =IF($A12>=E$2,ROUND(E$1*Parametry!$B$7^($A12-E$2),0),0) -> 5 | F12: =IF($A12>=F$2,ROUND(F$1*Parametry!$B$7^($A12-F$2),0),0) -> 3 | G12: =IF($A12>=G$2,ROUND(G$1*Parametry!$B$7^($A12-G$2),0),0) -> 3 | H12: =IF($A12>=H$2,ROUND(H$1*Parametry!$B$7^($A12-H$2),0),0) -> 3 | I12: =IF($A12>=I$2,ROUND(I$1*Parametry!$B$7^($A12-I$2),0),0) -> 2 | J12: =IF($A12>=J$2,ROUND(J$1*Parametry!$B$7^($A12-J$2),0),0) -> 1 | K12: =IF($A12>=K$2,ROUND(K$1*Parametry!$B$7^($A12-K$2),0),0) -> 0 | ... V12: =IF($A12>=V$2,ROUND(V$1*Parametry!$B$7^($A12-V$2),0),0) -> 0 | W12: =SUM(D12:V12) -> 34 | X12: =(D12*Nepřátelé!$B$2+E12*Nepřátelé!$B$3+F12*Nepřátelé!$B$4+G12*Nepřátelé!$B$5+H12*Nepřátelé!$B$6+I12*Nepřátelé!$B$7+J12*Nepřátelé!$B$8+K12*Nepřátelé!$B$9+L12*Nepřátelé!$B$10+M12*Nepřátelé!$B$11+N12*Nepřátelé!$B$12+O12*Nepřátelé!$B$13+P12*Nepřátelé!$B$14+Q12*Nepřátelé!$B$15+R12*Nepřátelé!$B$16+S12*Nepřátelé!$B$22+T12*Nepřátelé!$B$24+U12*Nepřátelé!$B$29+V12*Nepřátelé!$B$33)*B12 -> 5230.9291 | Y12: =(D12*Nepřátelé!$C$2+E12*Nepřátelé!$C$3+F12*Nepřátelé!$C$4+G12*Nepřátelé!$C$5+H12*Nepřátelé!$C$6+I12*Nepřátelé!$C$7+J12*Nepřátelé!$C$8+K12*Nepřátelé!$C$9+L12*Nepřátelé!$C$10+M12*Nepřátelé!$C$11+N12*Nepřátelé!$C$12+O12*Nepřátelé!$C$13+P12*Nepřátelé!$C$14+Q12*Nepřátelé!$C$15+R12*Nepřátelé!$C$16+S12*Nepřátelé!$C$22+T12*Nepřátelé!$C$24+U12*Nepřátelé!$C$29+V12*Nepřátelé!$C$33) -> 205 | Z12: =(D12*Nepřátelé!$E$2+E12*Nepřátelé!$E$3+F12*Nepřátelé!$E$4+G12*Nepřátelé!$E$5+H12*Nepřátelé!$E$6+I12*Nepřátelé!$E$7+J12*Nepřátelé!$E$8+K12*Nepřátelé!$E$9+L12*Nepřátelé!$E$10+M12*Nepřátelé!$E$11+N12*Nepřátelé!$E$12+O12*Nepřátelé!$E$13+P12*Nepřátelé!$E$14+Q12*Nepřátelé!$E$15+R12*Nepřátelé!$E$16+S12*Nepřátelé!$E$22+T12*Nepřátelé!$E$24+U12*Nepřátelé!$E$29+V12*Nepřátelé!$E$33)*B12^Parametry!$B$12 -> 686.81149 | AA12: =Parametry!$B$14+Parametry!$B$15*A12 -> 65 | AB12: =AB11+Z12+AA12 -> 2801.9425 | AC12: =X12/Parametry!$B$8 -> 116.24287 | AD12: =AC12*Parametry!$B$10 -> 81.370008 | AE12: =AB11*Parametry!$B$16*Zbraně!$B$40*Parametry!$B$11 -> 95.519093 | AF12: =IF(AD12=0,0,AE12/AD12) -> 1.1738857 | AG12: =IF(AF12<0.8,"TĚŽKÁ",IF(AF12>2,"LEHKÁ","OK")) -> OK
A13: 10 | B13: =Parametry!$B$6^(A13-1) -> 3.5178763 | C13: =Parametry!$B$7^(A13-1) -> 1.9990046 | D13: =IF($A13>=D$2,ROUND(D$1*Parametry!$B$7^($A13-D$2),0),0) -> 12 | E13: =IF($A13>=E$2,ROUND(E$1*Parametry!$B$7^($A13-E$2),0),0) -> 5 | F13: =IF($A13>=F$2,ROUND(F$1*Parametry!$B$7^($A13-F$2),0),0) -> 3 | G13: =IF($A13>=G$2,ROUND(G$1*Parametry!$B$7^($A13-G$2),0),0) -> 3 | H13: =IF($A13>=H$2,ROUND(H$1*Parametry!$B$7^($A13-H$2),0),0) -> 3 | I13: =IF($A13>=I$2,ROUND(I$1*Parametry!$B$7^($A13-I$2),0),0) -> 2 | J13: =IF($A13>=J$2,ROUND(J$1*Parametry!$B$7^($A13-J$2),0),0) -> 1 | K13: =IF($A13>=K$2,ROUND(K$1*Parametry!$B$7^($A13-K$2),0),0) -> 0 | ... V13: =IF($A13>=V$2,ROUND(V$1*Parametry!$B$7^($A13-V$2),0),0) -> 0 | W13: =SUM(D13:V13) -> 37 | X13: =(D13*Nepřátelé!$B$2+E13*Nepřátelé!$B$3+F13*Nepřátelé!$B$4+G13*Nepřátelé!$B$5+H13*Nepřátelé!$B$6+I13*Nepřátelé!$B$7+J13*Nepřátelé!$B$8+K13*Nepřátelé!$B$9+L13*Nepřátelé!$B$10+M13*Nepřátelé!$B$11+N13*Nepřátelé!$B$12+O13*Nepřátelé!$B$13+P13*Nepřátelé!$B$14+Q13*Nepřátelé!$B$15+R13*Nepřátelé!$B$16+S13*Nepřátelé!$B$22+T13*Nepřátelé!$B$24+U13*Nepřátelé!$B$29+V13*Nepřátelé!$B$33)*B13 -> 6596.018 | Y13: =(D13*Nepřátelé!$C$2+E13*Nepřátelé!$C$3+F13*Nepřátelé!$C$4+G13*Nepřátelé!$C$5+H13*Nepřátelé!$C$6+I13*Nepřátelé!$C$7+J13*Nepřátelé!$C$8+K13*Nepřátelé!$C$9+L13*Nepřátelé!$C$10+M13*Nepřátelé!$C$11+N13*Nepřátelé!$C$12+O13*Nepřátelé!$C$13+P13*Nepřátelé!$C$14+Q13*Nepřátelé!$C$15+R13*Nepřátelé!$C$16+S13*Nepřátelé!$C$22+T13*Nepřátelé!$C$24+U13*Nepřátelé!$C$29+V13*Nepřátelé!$C$33) -> 220 | Z13: =(D13*Nepřátelé!$E$2+E13*Nepřátelé!$E$3+F13*Nepřátelé!$E$4+G13*Nepřátelé!$E$5+H13*Nepřátelé!$E$6+I13*Nepřátelé!$E$7+J13*Nepřátelé!$E$8+K13*Nepřátelé!$E$9+L13*Nepřátelé!$E$10+M13*Nepřátelé!$E$11+N13*Nepřátelé!$E$12+O13*Nepřátelé!$E$13+P13*Nepřátelé!$E$14+Q13*Nepřátelé!$E$15+R13*Nepřátelé!$E$16+S13*Nepřátelé!$E$22+T13*Nepřátelé!$E$24+U13*Nepřátelé!$E$29+V13*Nepřátelé!$E$33)*B13^Parametry!$B$12 -> 851.47343 | AA13: =Parametry!$B$14+Parametry!$B$15*A13 -> 70 | AB13: =AB12+Z13+AA13 -> 3723.4159 | AC13: =X13/Parametry!$B$8 -> 146.57818 | AD13: =AC13*Parametry!$B$10 -> 102.60473 | AE13: =AB12*Parametry!$B$16*Zbraně!$B$40*Parametry!$B$11 -> 130.54727 | AF13: =IF(AD13=0,0,AE13/AD13) -> 1.2723319 | AG13: =IF(AF13<0.8,"TĚŽKÁ",IF(AF13>2,"LEHKÁ","OK")) -> OK | AH13: Babička/Starosta/Tchyně/Řetěz
A14: 11 | B14: =Parametry!$B$6^(A14-1) -> 4.0455577 | C14: =Parametry!$B$7^(A14-1) -> 2.158925 | D14: =IF($A14>=D$2,ROUND(D$1*Parametry!$B$7^($A14-D$2),0),0) -> 13 | E14: =IF($A14>=E$2,ROUND(E$1*Parametry!$B$7^($A14-E$2),0),0) -> 6 | F14: =IF($A14>=F$2,ROUND(F$1*Parametry!$B$7^($A14-F$2),0),0) -> 4 | G14: =IF($A14>=G$2,ROUND(G$1*Parametry!$B$7^($A14-G$2),0),0) -> 3 | H14: =IF($A14>=H$2,ROUND(H$1*Parametry!$B$7^($A14-H$2),0),0) -> 3 | I14: =IF($A14>=I$2,ROUND(I$1*Parametry!$B$7^($A14-I$2),0),0) -> 2 | J14: =IF($A14>=J$2,ROUND(J$1*Parametry!$B$7^($A14-J$2),0),0) -> 1 | K14: =IF($A14>=K$2,ROUND(K$1*Parametry!$B$7^($A14-K$2),0),0) -> 0 | ... V14: =IF($A14>=V$2,ROUND(V$1*Parametry!$B$7^($A14-V$2),0),0) -> 0 | W14: =SUM(D14:V14) -> 40 | X14: =(D14*Nepřátelé!$B$2+E14*Nepřátelé!$B$3+F14*Nepřátelé!$B$4+G14*Nepřátelé!$B$5+H14*Nepřátelé!$B$6+I14*Nepřátelé!$B$7+J14*Nepřátelé!$B$8+K14*Nepřátelé!$B$9+L14*Nepřátelé!$B$10+M14*Nepřátelé!$B$11+N14*Nepřátelé!$B$12+O14*Nepřátelé!$B$13+P14*Nepřátelé!$B$14+Q14*Nepřátelé!$B$15+R14*Nepřátelé!$B$16+S14*Nepřátelé!$B$22+T14*Nepřátelé!$B$24+U14*Nepřátelé!$B$29+V14*Nepřátelé!$B$33)*B14 -> 8091.1155 | Y14: =(D14*Nepřátelé!$C$2+E14*Nepřátelé!$C$3+F14*Nepřátelé!$C$4+G14*Nepřátelé!$C$5+H14*Nepřátelé!$C$6+I14*Nepřátelé!$C$7+J14*Nepřátelé!$C$8+K14*Nepřátelé!$C$9+L14*Nepřátelé!$C$10+M14*Nepřátelé!$C$11+N14*Nepřátelé!$C$12+O14*Nepřátelé!$C$13+P14*Nepřátelé!$C$14+Q14*Nepřátelé!$C$15+R14*Nepřátelé!$C$16+S14*Nepřátelé!$C$22+T14*Nepřátelé!$C$24+U14*Nepřátelé!$C$29+V14*Nepřátelé!$C$33) -> 242 | Z14: =(D14*Nepřátelé!$E$2+E14*Nepřátelé!$E$3+F14*Nepřátelé!$E$4+G14*Nepřátelé!$E$5+H14*Nepřátelé!$E$6+I14*Nepřátelé!$E$7+J14*Nepřátelé!$E$8+K14*Nepřátelé!$E$9+L14*Nepřátelé!$E$10+M14*Nepřátelé!$E$11+N14*Nepřátelé!$E$12+O14*Nepřátelé!$E$13+P14*Nepřátelé!$E$14+Q14*Nepřátelé!$E$15+R14*Nepřátelé!$E$16+S14*Nepřátelé!$E$22+T14*Nepřátelé!$E$24+U14*Nepřátelé!$E$29+V14*Nepřátelé!$E$33)*B14^Parametry!$B$12 -> 994.84744 | AA14: =Parametry!$B$14+Parametry!$B$15*A14 -> 75 | AB14: =AB13+Z14+AA14 -> 4793.2634 | AC14: =X14/Parametry!$B$8 -> 179.80257 | AD14: =AC14*Parametry!$B$10 -> 125.8618 | AE14: =AB13*Parametry!$B$16*Zbraně!$B$40*Parametry!$B$11 -> 173.48028 | AF14: =IF(AD14=0,0,AE14/AD14) -> 1.3783395 | AG14: =IF(AF14<0.8,"TĚŽKÁ",IF(AF14>2,"LEHKÁ","OK")) -> OK
A15: 12 | B15: =Parametry!$B$6^(A15-1) -> 4.6523914 | C15: =Parametry!$B$7^(A15-1) -> 2.331639 | D15: =IF($A15>=D$2,ROUND(D$1*Parametry!$B$7^($A15-D$2),0),0) -> 14 | E15: =IF($A15>=E$2,ROUND(E$1*Parametry!$B$7^($A15-E$2),0),0) -> 6 | F15: =IF($A15>=F$2,ROUND(F$1*Parametry!$B$7^($A15-F$2),0),0) -> 4 | G15: =IF($A15>=G$2,ROUND(G$1*Parametry!$B$7^($A15-G$2),0),0) -> 3 | H15: =IF($A15>=H$2,ROUND(H$1*Parametry!$B$7^($A15-H$2),0),0) -> 3 | I15: =IF($A15>=I$2,ROUND(I$1*Parametry!$B$7^($A15-I$2),0),0) -> 3 | J15: =IF($A15>=J$2,ROUND(J$1*Parametry!$B$7^($A15-J$2),0),0) -> 1 | K15: =IF($A15>=K$2,ROUND(K$1*Parametry!$B$7^($A15-K$2),0),0) -> 1 | ... V15: =IF($A15>=V$2,ROUND(V$1*Parametry!$B$7^($A15-V$2),0),0) -> 0 | W15: =SUM(D15:V15) -> 45 | X15: =(D15*Nepřátelé!$B$2+E15*Nepřátelé!$B$3+F15*Nepřátelé!$B$4+G15*Nepřátelé!$B$5+H15*Nepřátelé!$B$6+I15*Nepřátelé!$B$7+J15*Nepřátelé!$B$8+K15*Nepřátelé!$B$9+L15*Nepřátelé!$B$10+M15*Nepřátelé!$B$11+N15*Nepřátelé!$B$12+O15*Nepřátelé!$B$13+P15*Nepřátelé!$B$14+Q15*Nepřátelé!$B$15+R15*Nepřátelé!$B$16+S15*Nepřátelé!$B$22+T15*Nepřátelé!$B$24+U15*Nepřátelé!$B$29+V15*Nepřátelé!$B$33)*B15 -> 10188.737 | Y15: =(D15*Nepřátelé!$C$2+E15*Nepřátelé!$C$3+F15*Nepřátelé!$C$4+G15*Nepřátelé!$C$5+H15*Nepřátelé!$C$6+I15*Nepřátelé!$C$7+J15*Nepřátelé!$C$8+K15*Nepřátelé!$C$9+L15*Nepřátelé!$C$10+M15*Nepřátelé!$C$11+N15*Nepřátelé!$C$12+O15*Nepřátelé!$C$13+P15*Nepřátelé!$C$14+Q15*Nepřátelé!$C$15+R15*Nepřátelé!$C$16+S15*Nepřátelé!$C$22+T15*Nepřátelé!$C$24+U15*Nepřátelé!$C$29+V15*Nepřátelé!$C$33) -> 262 | Z15: =(D15*Nepřátelé!$E$2+E15*Nepřátelé!$E$3+F15*Nepřátelé!$E$4+G15*Nepřátelé!$E$5+H15*Nepřátelé!$E$6+I15*Nepřátelé!$E$7+J15*Nepřátelé!$E$8+K15*Nepřátelé!$E$9+L15*Nepřátelé!$E$10+M15*Nepřátelé!$E$11+N15*Nepřátelé!$E$12+O15*Nepřátelé!$E$13+P15*Nepřátelé!$E$14+Q15*Nepřátelé!$E$15+R15*Nepřátelé!$E$16+S15*Nepřátelé!$E$22+T15*Nepřátelé!$E$24+U15*Nepřátelé!$E$29+V15*Nepřátelé!$E$33)*B15^Parametry!$B$12 -> 1328.8366 | AA15: =Parametry!$B$14+Parametry!$B$15*A15 -> 80 | AB15: =AB14+Z15+AA15 -> 6202.0999 | AC15: =X15/Parametry!$B$8 -> 226.41638 | AD15: =AC15*Parametry!$B$10 -> 158.49147 | AE15: =AB14*Parametry!$B$16*Zbraně!$B$40*Parametry!$B$11 -> 223.3263 | AF15: =IF(AD15=0,0,AE15/AD15) -> 1.4090746 | AG15: =IF(AF15<0.8,"TĚŽKÁ",IF(AF15>2,"LEHKÁ","OK")) -> OK
A16: 13 | B16: =Parametry!$B$6^(A16-1) -> 5.3502501 | C16: =Parametry!$B$7^(A16-1) -> 2.5181701 | D16: =IF($A16>=D$2,ROUND(D$1*Parametry!$B$7^($A16-D$2),0),0) -> 15 | E16: =IF($A16>=E$2,ROUND(E$1*Parametry!$B$7^($A16-E$2),0),0) -> 6 | F16: =IF($A16>=F$2,ROUND(F$1*Parametry!$B$7^($A16-F$2),0),0) -> 4 | G16: =IF($A16>=G$2,ROUND(G$1*Parametry!$B$7^($A16-G$2),0),0) -> 3 | H16: =IF($A16>=H$2,ROUND(H$1*Parametry!$B$7^($A16-H$2),0),0) -> 3 | I16: =IF($A16>=I$2,ROUND(I$1*Parametry!$B$7^($A16-I$2),0),0) -> 3 | J16: =IF($A16>=J$2,ROUND(J$1*Parametry!$B$7^($A16-J$2),0),0) -> 1 | K16: =IF($A16>=K$2,ROUND(K$1*Parametry!$B$7^($A16-K$2),0),0) -> 1 | ... V16: =IF($A16>=V$2,ROUND(V$1*Parametry!$B$7^($A16-V$2),0),0) -> 0 | W16: =SUM(D16:V16) -> 47 | X16: =(D16*Nepřátelé!$B$2+E16*Nepřátelé!$B$3+F16*Nepřátelé!$B$4+G16*Nepřátelé!$B$5+H16*Nepřátelé!$B$6+I16*Nepřátelé!$B$7+J16*Nepřátelé!$B$8+K16*Nepřátelé!$B$9+L16*Nepřátelé!$B$10+M16*Nepřátelé!$B$11+N16*Nepřátelé!$B$12+O16*Nepřátelé!$B$13+P16*Nepřátelé!$B$14+Q16*Nepřátelé!$B$15+R16*Nepřátelé!$B$16+S16*Nepřátelé!$B$22+T16*Nepřátelé!$B$24+U16*Nepřátelé!$B$29+V16*Nepřátelé!$B$33)*B16 -> 12947.605 | Y16: =(D16*Nepřátelé!$C$2+E16*Nepřátelé!$C$3+F16*Nepřátelé!$C$4+G16*Nepřátelé!$C$5+H16*Nepřátelé!$C$6+I16*Nepřátelé!$C$7+J16*Nepřátelé!$C$8+K16*Nepřátelé!$C$9+L16*Nepřátelé!$C$10+M16*Nepřátelé!$C$11+N16*Nepřátelé!$C$12+O16*Nepřátelé!$C$13+P16*Nepřátelé!$C$14+Q16*Nepřátelé!$C$15+R16*Nepřátelé!$C$16+S16*Nepřátelé!$C$22+T16*Nepřátelé!$C$24+U16*Nepřátelé!$C$29+V16*Nepřátelé!$C$33) -> 281 | Z16: =(D16*Nepřátelé!$E$2+E16*Nepřátelé!$E$3+F16*Nepřátelé!$E$4+G16*Nepřátelé!$E$5+H16*Nepřátelé!$E$6+I16*Nepřátelé!$E$7+J16*Nepřátelé!$E$8+K16*Nepřátelé!$E$9+L16*Nepřátelé!$E$10+M16*Nepřátelé!$E$11+N16*Nepřátelé!$E$12+O16*Nepřátelé!$E$13+P16*Nepřátelé!$E$14+Q16*Nepřátelé!$E$15+R16*Nepřátelé!$E$16+S16*Nepřátelé!$E$22+T16*Nepřátelé!$E$24+U16*Nepřátelé!$E$29+V16*Nepřátelé!$E$33)*B16^Parametry!$B$12 -> 1572.165 | AA16: =Parametry!$B$14+Parametry!$B$15*A16 -> 85 | AB16: =AB15+Z16+AA16 -> 7859.265 | AC16: =X16/Parametry!$B$8 -> 287.72456 | AD16: =AC16*Parametry!$B$10 -> 201.40719 | AE16: =AB15*Parametry!$B$16*Zbraně!$B$40*Parametry!$B$11 -> 288.96639 | AF16: =IF(AD16=0,0,AE16/AD16) -> 1.4347372 | AG16: =IF(AF16<0.8,"TĚŽKÁ",IF(AF16>2,"LEHKÁ","OK")) -> OK
A17: 14 | B17: =Parametry!$B$6^(A17-1) -> 6.1527876 | C17: =Parametry!$B$7^(A17-1) -> 2.7196237 | D17: =IF($A17>=D$2,ROUND(D$1*Parametry!$B$7^($A17-D$2),0),0) -> 16 | E17: =IF($A17>=E$2,ROUND(E$1*Parametry!$B$7^($A17-E$2),0),0) -> 7 | F17: =IF($A17>=F$2,ROUND(F$1*Parametry!$B$7^($A17-F$2),0),0) -> 5 | G17: =IF($A17>=G$2,ROUND(G$1*Parametry!$B$7^($A17-G$2),0),0) -> 4 | H17: =IF($A17>=H$2,ROUND(H$1*Parametry!$B$7^($A17-H$2),0),0) -> 4 | I17: =IF($A17>=I$2,ROUND(I$1*Parametry!$B$7^($A17-I$2),0),0) -> 3 | J17: =IF($A17>=J$2,ROUND(J$1*Parametry!$B$7^($A17-J$2),0),0) -> 1 | K17: =IF($A17>=K$2,ROUND(K$1*Parametry!$B$7^($A17-K$2),0),0) -> 1 | ... V17: =IF($A17>=V$2,ROUND(V$1*Parametry!$B$7^($A17-V$2),0),0) -> 0 | W17: =SUM(D17:V17) -> 53 | X17: =(D17*Nepřátelé!$B$2+E17*Nepřátelé!$B$3+F17*Nepřátelé!$B$4+G17*Nepřátelé!$B$5+H17*Nepřátelé!$B$6+I17*Nepřátelé!$B$7+J17*Nepřátelé!$B$8+K17*Nepřátelé!$B$9+L17*Nepřátelé!$B$10+M17*Nepřátelé!$B$11+N17*Nepřátelé!$B$12+O17*Nepřátelé!$B$13+P17*Nepřátelé!$B$14+Q17*Nepřátelé!$B$15+R17*Nepřátelé!$B$16+S17*Nepřátelé!$B$22+T17*Nepřátelé!$B$24+U17*Nepřátelé!$B$29+V17*Nepřátelé!$B$33)*B17 -> 17320.097 | Y17: =(D17*Nepřátelé!$C$2+E17*Nepřátelé!$C$3+F17*Nepřátelé!$C$4+G17*Nepřátelé!$C$5+H17*Nepřátelé!$C$6+I17*Nepřátelé!$C$7+J17*Nepřátelé!$C$8+K17*Nepřátelé!$C$9+L17*Nepřátelé!$C$10+M17*Nepřátelé!$C$11+N17*Nepřátelé!$C$12+O17*Nepřátelé!$C$13+P17*Nepřátelé!$C$14+Q17*Nepřátelé!$C$15+R17*Nepřátelé!$C$16+S17*Nepřátelé!$C$22+T17*Nepřátelé!$C$24+U17*Nepřátelé!$C$29+V17*Nepřátelé!$C$33) -> 322 | Z17: =(D17*Nepřátelé!$E$2+E17*Nepřátelé!$E$3+F17*Nepřátelé!$E$4+G17*Nepřátelé!$E$5+H17*Nepřátelé!$E$6+I17*Nepřátelé!$E$7+J17*Nepřátelé!$E$8+K17*Nepřátelé!$E$9+L17*Nepřátelé!$E$10+M17*Nepřátelé!$E$11+N17*Nepřátelé!$E$12+O17*Nepřátelé!$E$13+P17*Nepřátelé!$E$14+Q17*Nepřátelé!$E$15+R17*Nepřátelé!$E$16+S17*Nepřátelé!$E$22+T17*Nepřátelé!$E$24+U17*Nepřátelé!$E$29+V17*Nepřátelé!$E$33)*B17^Parametry!$B$12 -> 1976.333 | AA17: =Parametry!$B$14+Parametry!$B$15*A17 -> 90 | AB17: =AB16+Z17+AA17 -> 9925.5979 | AC17: =X17/Parametry!$B$8 -> 384.89105 | AD17: =AC17*Parametry!$B$10 -> 269.42373 | AE17: =AB16*Parametry!$B$16*Zbraně!$B$40*Parametry!$B$11 -> 366.17653 | AF17: =IF(AD17=0,0,AE17/AD17) -> 1.3591101 | AG17: =IF(AF17<0.8,"TĚŽKÁ",IF(AF17>2,"LEHKÁ","OK")) -> OK
A18: 15 | B18: =Parametry!$B$6^(A18-1) -> 7.0757058 | C18: =Parametry!$B$7^(A18-1) -> 2.9371936 | D18: =IF($A18>=D$2,ROUND(D$1*Parametry!$B$7^($A18-D$2),0),0) -> 18 | E18: =IF($A18>=E$2,ROUND(E$1*Parametry!$B$7^($A18-E$2),0),0) -> 8 | F18: =IF($A18>=F$2,ROUND(F$1*Parametry!$B$7^($A18-F$2),0),0) -> 5 | G18: =IF($A18>=G$2,ROUND(G$1*Parametry!$B$7^($A18-G$2),0),0) -> 4 | H18: =IF($A18>=H$2,ROUND(H$1*Parametry!$B$7^($A18-H$2),0),0) -> 4 | I18: =IF($A18>=I$2,ROUND(I$1*Parametry!$B$7^($A18-I$2),0),0) -> 3 | J18: =IF($A18>=J$2,ROUND(J$1*Parametry!$B$7^($A18-J$2),0),0) -> 2 | K18: =IF($A18>=K$2,ROUND(K$1*Parametry!$B$7^($A18-K$2),0),0) -> 1 | ... V18: =IF($A18>=V$2,ROUND(V$1*Parametry!$B$7^($A18-V$2),0),0) -> 0 | W18: =SUM(D18:V18) -> 61 | X18: =(D18*Nepřátelé!$B$2+E18*Nepřátelé!$B$3+F18*Nepřátelé!$B$4+G18*Nepřátelé!$B$5+H18*Nepřátelé!$B$6+I18*Nepřátelé!$B$7+J18*Nepřátelé!$B$8+K18*Nepřátelé!$B$9+L18*Nepřátelé!$B$10+M18*Nepřátelé!$B$11+N18*Nepřátelé!$B$12+O18*Nepřátelé!$B$13+P18*Nepřátelé!$B$14+Q18*Nepřátelé!$B$15+R18*Nepřátelé!$B$16+S18*Nepřátelé!$B$22+T18*Nepřátelé!$B$24+U18*Nepřátelé!$B$29+V18*Nepřátelé!$B$33)*B18 -> 23774.371 | Y18: =(D18*Nepřátelé!$C$2+E18*Nepřátelé!$C$3+F18*Nepřátelé!$C$4+G18*Nepřátelé!$C$5+H18*Nepřátelé!$C$6+I18*Nepřátelé!$C$7+J18*Nepřátelé!$C$8+K18*Nepřátelé!$C$9+L18*Nepřátelé!$C$10+M18*Nepřátelé!$C$11+N18*Nepřátelé!$C$12+O18*Nepřátelé!$C$13+P18*Nepřátelé!$C$14+Q18*Nepřátelé!$C$15+R18*Nepřátelé!$C$16+S18*Nepřátelé!$C$22+T18*Nepřátelé!$C$24+U18*Nepřátelé!$C$29+V18*Nepřátelé!$C$33) -> 422 | Z18: =(D18*Nepřátelé!$E$2+E18*Nepřátelé!$E$3+F18*Nepřátelé!$E$4+G18*Nepřátelé!$E$5+H18*Nepřátelé!$E$6+I18*Nepřátelé!$E$7+J18*Nepřátelé!$E$8+K18*Nepřátelé!$E$9+L18*Nepřátelé!$E$10+M18*Nepřátelé!$E$11+N18*Nepřátelé!$E$12+O18*Nepřátelé!$E$13+P18*Nepřátelé!$E$14+Q18*Nepřátelé!$E$15+R18*Nepřátelé!$E$16+S18*Nepřátelé!$E$22+T18*Nepřátelé!$E$24+U18*Nepřátelé!$E$29+V18*Nepřátelé!$E$33)*B18^Parametry!$B$12 -> 2659.4114 | AA18: =Parametry!$B$14+Parametry!$B$15*A18 -> 95 | AB18: =AB17+Z18+AA18 -> 12680.009 | AC18: =X18/Parametry!$B$8 -> 528.31936 | AD18: =AC18*Parametry!$B$10 -> 369.82355 | AE18: =AB17*Parametry!$B$16*Zbraně!$B$40*Parametry!$B$11 -> 462.4505 | AF18: =IF(AD18=0,0,AE18/AD18) -> 1.2504625 | AG18: =IF(AF18<0.8,"TĚŽKÁ",IF(AF18>2,"LEHKÁ","OK")) -> OK | AH18: minibos
A19: 16 | B19: =Parametry!$B$6^(A19-1) -> 8.1370616 | C19: =Parametry!$B$7^(A19-1) -> 3.1721691 | D19: =IF($A19>=D$2,ROUND(D$1*Parametry!$B$7^($A19-D$2),0),0) -> 19 | E19: =IF($A19>=E$2,ROUND(E$1*Parametry!$B$7^($A19-E$2),0),0) -> 8 | F19: =IF($A19>=F$2,ROUND(F$1*Parametry!$B$7^($A19-F$2),0),0) -> 5 | G19: =IF($A19>=G$2,ROUND(G$1*Parametry!$B$7^($A19-G$2),0),0) -> 4 | H19: =IF($A19>=H$2,ROUND(H$1*Parametry!$B$7^($A19-H$2),0),0) -> 4 | I19: =IF($A19>=I$2,ROUND(I$1*Parametry!$B$7^($A19-I$2),0),0) -> 3 | J19: =IF($A19>=J$2,ROUND(J$1*Parametry!$B$7^($A19-J$2),0),0) -> 2 | K19: =IF($A19>=K$2,ROUND(K$1*Parametry!$B$7^($A19-K$2),0),0) -> 1 | ... V19: =IF($A19>=V$2,ROUND(V$1*Parametry!$B$7^($A19-V$2),0),0) -> 0 | W19: =SUM(D19:V19) -> 63 | X19: =(D19*Nepřátelé!$B$2+E19*Nepřátelé!$B$3+F19*Nepřátelé!$B$4+G19*Nepřátelé!$B$5+H19*Nepřátelé!$B$6+I19*Nepřátelé!$B$7+J19*Nepřátelé!$B$8+K19*Nepřátelé!$B$9+L19*Nepřátelé!$B$10+M19*Nepřátelé!$B$11+N19*Nepřátelé!$B$12+O19*Nepřátelé!$B$13+P19*Nepřátelé!$B$14+Q19*Nepřátelé!$B$15+R19*Nepřátelé!$B$16+S19*Nepřátelé!$B$22+T19*Nepřátelé!$B$24+U19*Nepřátelé!$B$29+V19*Nepřátelé!$B$33)*B19 -> 28316.974 | Y19: =(D19*Nepřátelé!$C$2+E19*Nepřátelé!$C$3+F19*Nepřátelé!$C$4+G19*Nepřátelé!$C$5+H19*Nepřátelé!$C$6+I19*Nepřátelé!$C$7+J19*Nepřátelé!$C$8+K19*Nepřátelé!$C$9+L19*Nepřátelé!$C$10+M19*Nepřátelé!$C$11+N19*Nepřátelé!$C$12+O19*Nepřátelé!$C$13+P19*Nepřátelé!$C$14+Q19*Nepřátelé!$C$15+R19*Nepřátelé!$C$16+S19*Nepřátelé!$C$22+T19*Nepřátelé!$C$24+U19*Nepřátelé!$C$29+V19*Nepřátelé!$C$33) -> 432 | Z19: =(D19*Nepřátelé!$E$2+E19*Nepřátelé!$E$3+F19*Nepřátelé!$E$4+G19*Nepřátelé!$E$5+H19*Nepřátelé!$E$6+I19*Nepřátelé!$E$7+J19*Nepřátelé!$E$8+K19*Nepřátelé!$E$9+L19*Nepřátelé!$E$10+M19*Nepřátelé!$E$11+N19*Nepřátelé!$E$12+O19*Nepřátelé!$E$13+P19*Nepřátelé!$E$14+Q19*Nepřátelé!$E$15+R19*Nepřátelé!$E$16+S19*Nepřátelé!$E$22+T19*Nepřátelé!$E$24+U19*Nepřátelé!$E$29+V19*Nepřátelé!$E$33)*B19^Parametry!$B$12 -> 3049.8793 | AA19: =Parametry!$B$14+Parametry!$B$15*A19 -> 100 | AB19: =AB18+Z19+AA19 -> 15829.889 | AC19: =X19/Parametry!$B$8 -> 629.2661 | AD19: =AC19*Parametry!$B$10 -> 440.48627 | AE19: =AB18*Parametry!$B$16*Zbraně!$B$40*Parametry!$B$11 -> 590.78321 | AF19: =IF(AD19=0,0,AE19/AD19) -> 1.3412069 | AG19: =IF(AF19<0.8,"TĚŽKÁ",IF(AF19>2,"LEHKÁ","OK")) -> OK
A20: 17 | B20: =Parametry!$B$6^(A20-1) -> 9.3576209 | C20: =Parametry!$B$7^(A20-1) -> 3.4259426 | D20: =IF($A20>=D$2,ROUND(D$1*Parametry!$B$7^($A20-D$2),0),0) -> 21 | E20: =IF($A20>=E$2,ROUND(E$1*Parametry!$B$7^($A20-E$2),0),0) -> 9 | F20: =IF($A20>=F$2,ROUND(F$1*Parametry!$B$7^($A20-F$2),0),0) -> 6 | G20: =IF($A20>=G$2,ROUND(G$1*Parametry!$B$7^($A20-G$2),0),0) -> 5 | H20: =IF($A20>=H$2,ROUND(H$1*Parametry!$B$7^($A20-H$2),0),0) -> 5 | I20: =IF($A20>=I$2,ROUND(I$1*Parametry!$B$7^($A20-I$2),0),0) -> 4 | J20: =IF($A20>=J$2,ROUND(J$1*Parametry!$B$7^($A20-J$2),0),0) -> 2 | K20: =IF($A20>=K$2,ROUND(K$1*Parametry!$B$7^($A20-K$2),0),0) -> 1 | ... V20: =IF($A20>=V$2,ROUND(V$1*Parametry!$B$7^($A20-V$2),0),0) -> 0 | W20: =SUM(D20:V20) -> 70 | X20: =(D20*Nepřátelé!$B$2+E20*Nepřátelé!$B$3+F20*Nepřátelé!$B$4+G20*Nepřátelé!$B$5+H20*Nepřátelé!$B$6+I20*Nepřátelé!$B$7+J20*Nepřátelé!$B$8+K20*Nepřátelé!$B$9+L20*Nepřátelé!$B$10+M20*Nepřátelé!$B$11+N20*Nepřátelé!$B$12+O20*Nepřátelé!$B$13+P20*Nepřátelé!$B$14+Q20*Nepřátelé!$B$15+R20*Nepřátelé!$B$16+S20*Nepřátelé!$B$22+T20*Nepřátelé!$B$24+U20*Nepřátelé!$B$29+V20*Nepřátelé!$B$33)*B20 -> 36307.569 | Y20: =(D20*Nepřátelé!$C$2+E20*Nepřátelé!$C$3+F20*Nepřátelé!$C$4+G20*Nepřátelé!$C$5+H20*Nepřátelé!$C$6+I20*Nepřátelé!$C$7+J20*Nepřátelé!$C$8+K20*Nepřátelé!$C$9+L20*Nepřátelé!$C$10+M20*Nepřátelé!$C$11+N20*Nepřátelé!$C$12+O20*Nepřátelé!$C$13+P20*Nepřátelé!$C$14+Q20*Nepřátelé!$C$15+R20*Nepřátelé!$C$16+S20*Nepřátelé!$C$22+T20*Nepřátelé!$C$24+U20*Nepřátelé!$C$29+V20*Nepřátelé!$C$33) -> 483 | Z20: =(D20*Nepřátelé!$E$2+E20*Nepřátelé!$E$3+F20*Nepřátelé!$E$4+G20*Nepřátelé!$E$5+H20*Nepřátelé!$E$6+I20*Nepřátelé!$E$7+J20*Nepřátelé!$E$8+K20*Nepřátelé!$E$9+L20*Nepřátelé!$E$10+M20*Nepřátelé!$E$11+N20*Nepřátelé!$E$12+O20*Nepřátelé!$E$13+P20*Nepřátelé!$E$14+Q20*Nepřátelé!$E$15+R20*Nepřátelé!$E$16+S20*Nepřátelé!$E$22+T20*Nepřátelé!$E$24+U20*Nepřátelé!$E$29+V20*Nepřátelé!$E$33)*B20^Parametry!$B$12 -> 3703.0261 | AA20: =Parametry!$B$14+Parametry!$B$15*A20 -> 105 | AB20: =AB19+Z20+AA20 -> 19637.915 | AC20: =X20/Parametry!$B$8 -> 806.83487 | AD20: =AC20*Parametry!$B$10 -> 564.78441 | AE20: =AB19*Parametry!$B$16*Zbraně!$B$40*Parametry!$B$11 -> 737.54145 | AF20: =IF(AD20=0,0,AE20/AD20) -> 1.3058814 | AG20: =IF(AF20<0.8,"TĚŽKÁ",IF(AF20>2,"LEHKÁ","OK")) -> OK
